Workbook

Sheet A LIRE
A1: Document : | C1: Outil de nomenclature SIAD
A3: Interlocuteurs : | C3: Angéline JACQUINOT | D3: Carole ANDREOTTI
A5: Ce document permet de générer les codes des tables et champs d'une nomenclature ainsi que des libellés anglais. Il est là pour aider à compléter la demande de nomenclature.
A6: Il est décomposé en 4 parties : Tables, Champs, Objets de gestion/Articles et BIB/Type de table/Type de champ
A8: La feuille "Tables" permet de générer le code des tables (Domaine de valeurs et Datamart compris)
A9: À faire : | B9: Complèter les colonnes (par sélection dans la liste déroulante) : Nom du BIB, Type de table et Objet de gestion (jusquà 4 objets de gestion possible par table)
B10: ATTENTION : les colonnes après la barre vertical noire sont générés par du code Excel, merci de ne pas les toucher
A12: La feuille "Champs" permet de générer le code des champs (UID, code et libellé des domaines de valeurs compris).
A13: À faire : | B13: Complèter les colonnes (par sélection dans la liste déroulante) : Nom du BIB, Type de champ, Nature, Article + Objet de gestion et Ordre des trigrammes (jusquà 4 objets de gestion possible par champ)
B14: Ordre des trigrammes : "Normal" pour que le dernier objet de gestion soit au début. Ex : Le code de l'état du contrat > X_CTR_STT_COD > Contract state code "Forcé" pour que l'ordre des trigrammes soit le même que le libelé. Ex : : Le code de l'état du contrat > X_STT_CTR_COD > State contract code
B15: ATTENTION : les colonnes après la barre vertical noire sont générés par du code Excel, merci de ne pas les toucher
A17: Les feuilles "Objets de gestion" et "Articles" sont des référentiels. Ils peuvent être agrémenter de nouvelles lignes mais en aucun cas être mofifiés.
A18: À faire : | B18: Si un Objet de gestion n'est pas présent : - insérer une nouvelle ligne dans le tableau (Ctrl + "+") ou placer vous à la fin du tableau - renseigner la date du jour, le nom français, une description si besoin, le nom anglais et le trigramme (si le trigramme n'est pas présent dans LISABR, le surligner en rouge) - trier la colonne "nom FR" de A à Z Si un Article n'est pas présent : - insérer une nouvelle ligne dans le tableau (Ctrl + "+") ou placer vous à la fin du tableau - renseigner l'article en français et son équivalent anglais - trier sur la colonne "nom FR" de A à Z
A20: Les feuilles "BIB", "Type de table" et "Type de champ" sont des référentiels qui ne doivent pas être modifiés.
B21: Merci de notifier la cellule si une information est manquante.

Sheet Tables
A1: Nom du BIB | B1: Type table | C1: Objet de gestion 1 | D1: Objet de gestion 2 | E1: Objet de gestion 3 | F1: Objet de gestion 4 | G1: Robin | H1: Nb car | I1: Code | J1: Nom français | K1: Nom anglais | L1: Type
A2: tiers | B2: Axe d'analyse | C2: Lien | D2: tiers | E2: chargé de clientèle | G2: =IF(ISBLANK(A2),"",LOOKUP(A2,BIB!A:A,BIB!C:C)) -> IBIA | H2: =IF(AND(ISBLANK(A2),ISBLANK(B2),ISBLANK(C2)),"",IF(OR(ISBLANK(A2),ISBLANK(B2),ISBLANK(C2)),"-",LEN(Tableau4[[#This Row],[Colonne9]]))) -> 19 | I2: =IF(AND(ISBLANK(A2),ISBLANK(B2),ISBLANK(C2)),"",IF(OR(ISBLANK(A2),ISBLANK(B2),ISBLANK(C2)),"à compléter",UPPER(LOOKUP(A2,BIB!A:A,BIB!B:B)&LOOKUP(B2,'Type de table'!C:C,'Type de table'!B:B) &IF(COUNTIF('Objets de gestion'!C:C,F2)=0,"","_"&LOOKUP(F2,'Objets de gestion'!C:C,'Objets de gestion'!F:F)) &IF(COUNTIF('Objets de gestion'!C:C,E2)=0,"","_"&LOOKUP(E2,'Objets de gestion'!C:C,'Objets de gestion'!F:F)) &IF(COUNTIF('Objets de gestion'!C:C,D2)=0,"","_"&LOOKUP(D2,'Objets de gestion'!C:C,'Objets de gestion'!F:F)) &IF(COUNTIF('Objets de gestion'!C:C,C2)=0,"","_"&LOOKUP(C2,'Objets de gestion'!C:C,'Objets de gestion'!F:F)) ))) -> ATIX_ACCMGR_TDP_LNK | J2: =IF(AND(ISBLANK(A2),ISBLANK(B2),ISBLANK(C2)),"",IF(OR(ISBLANK(A2),ISBLANK(B2),ISBLANK(C2)),"-", LOOKUP(B2,'Type de table'!C:C,'Type de table'!E:E) &IF(ISBLANK(C2),""," "&C2) &IF(ISBLANK(D2),""," "&D2) &IF(ISBLANK(E2),""," "&E2) &IF(ISBLANK(F2),""," "&F2) )) -> Axe Lien tiers chargé de clientèle | K2: =IF(AND(ISBLANK(A2),ISBLANK(B2),ISBLANK(C2)),"",IF(OR(ISBLANK(A2),ISBLANK(B2),ISBLANK(C2)),"-", LOOKUP(B2,'Type de table'!C:C,'Type de table'!F:F) &IF(ISBLANK(C2),""," "&LOOKUP(C2,'Objets de gestion'!C:C,'Objets de gestion'!E:E)) &IF(ISBLANK(D2),""," "&LOOKUP(D2,'Objets de gestion'!C:C,'Objets de gestion'!E:E)) &IF(ISBLANK(E2),""," "&LOOKUP(E2,'Objets de gestion'!C:C,'Objets de gestion'!E:E)) &IF(ISBLANK(F2),""," "&LOOKUP(F2,'Objets de gestion'!C:C,'Objets de gestion'!E:E)) )) -> Axis Link third party Account Manager | L2: =IF(AND(ISBLANK(A2),ISBLANK(B2),ISBLANK(C2)),"",IF(OR(ISBLANK(A2),ISBLANK(B2),ISBLANK(C2)),"-",B2)) -> Axe d'analyse
A3: tiers | B3: Relation | C3: chargé de clientèle | D3: client | G3: =IF(ISBLANK(A3),"",LOOKUP(A3,BIB!A:A,BIB!C:C)) -> IBIA | H3: =IF(AND(ISBLANK(A3),ISBLANK(B3),ISBLANK(C3)),"",IF(OR(ISBLANK(A3),ISBLANK(B3),ISBLANK(C3)),"-",LEN(Tableau4[[#This Row],[Colonne9]]))) -> 15 | I3: =IF(AND(ISBLANK(A3),ISBLANK(B3),ISBLANK(C3)),"",IF(OR(ISBLANK(A3),ISBLANK(B3),ISBLANK(C3)),"à compléter",UPPER(LOOKUP(A3,BIB!A:A,BIB!B:B)&LOOKUP(B3,'Type de table'!C:C,'Type de table'!B:B) &IF(COUNTIF('Objets de gestion'!C:C,F3)=0,"","_"&LOOKUP(F3,'Objets de gestion'!C:C,'Objets de gestion'!F:F)) &IF(COUNTIF('Objets de gestion'!C:C,E3)=0,"","_"&LOOKUP(E3,'Objets de gestion'!C:C,'Objets de gestion'!F:F)) &IF(COUNTIF('Objets de gestion'!C:C,D3)=0,"","_"&LOOKUP(D3,'Objets de gestion'!C:C,'Objets de gestion'!F:F)) &IF(COUNTIF('Objets de gestion'!C:C,C3)=0,"","_"&LOOKUP(C3,'Objets de gestion'!C:C,'Objets de gestion'!F:F)) ))) -> ATIL_CUS_ACCMGR | J3: =IF(AND(ISBLANK(A3),ISBLANK(B3),ISBLANK(C3)),"",IF(OR(ISBLANK(A3),ISBLANK(B3),ISBLANK(C3)),"-", LOOKUP(B3,'Type de table'!C:C,'Type de table'!E:E) &IF(ISBLANK(C3),""," "&C3) &IF(ISBLANK(D3),""," "&D3) &IF(ISBLANK(E3),""," "&E3) &IF(ISBLANK(F3),""," "&F3) )) -> Table de lien entre chargé de clientèle client | K3: =IF(AND(ISBLANK(A3),ISBLANK(B3),ISBLANK(C3)),"",IF(OR(ISBLANK(A3),ISBLANK(B3),ISBLANK(C3)),"-", LOOKUP(B3,'Type de table'!C:C,'Type de table'!F:F) &IF(ISBLANK(C3),""," "&LOOKUP(C3,'Objets de gestion'!C:C,'Objets de gestion'!E:E)) &IF(ISBLANK(D3),""," "&LOOKUP(D3,'Objets de gestion'!C:C,'Objets de gestion'!E:E)) &IF(ISBLANK(E3),""," "&LOOKUP(E3,'Objets de gestion'!C:C,'Objets de gestion'!E:E)) &IF(ISBLANK(F3),""," "&LOOKUP(F3,'Objets de gestion'!C:C,'Objets de gestion'!E:E)) )) -> Link table between Account Manager customer | L3: =IF(AND(ISBLANK(A3),ISBLANK(B3),ISBLANK(C3)),"",IF(OR(ISBLANK(A3),ISBLANK(B3),ISBLANK(C3)),"-",B3)) -> Relation
G4: =IF(ISBLANK(A4),"",LOOKUP(A4,BIB!A:A,BIB!C:C))
G5: =IF(ISBLANK(A5),"",LOOKUP(A5,BIB!A:A,BIB!C:C))
G6: =IF(ISBLANK(A6),"",LOOKUP(A6,BIB!A:A,BIB!C:C))
G7: =IF(ISBLANK(A7),"",LOOKUP(A7,BIB!A:A,BIB!C:C))
G8: =IF(ISBLANK(A8),"",LOOKUP(A8,BIB!A:A,BIB!C:C))
G9: =IF(ISBLANK(A9),"",LOOKUP(A9,BIB!A:A,BIB!C:C))
G10: =IF(ISBLANK(A10),"",LOOKUP(A10,BIB!A:A,BIB!C:C))
G11: =IF(ISBLANK(A11),"",LOOKUP(A11,BIB!A:A,BIB!C:C))
G12: =IF(ISBLANK(A12),"",LOOKUP(A12,BIB!A:A,BIB!C:C))
G13: =IF(ISBLANK(A13),"",LOOKUP(A13,BIB!A:A,BIB!C:C))
G14: =IF(ISBLANK(A14),"",LOOKUP(A14,BIB!A:A,BIB!C:C))
G15: =IF(ISBLANK(A15),"",LOOKUP(A15,BIB!A:A,BIB!C:C))
G16: =IF(ISBLANK(A16),"",LOOKUP(A16,BIB!A:A,BIB!C:C)) | H16: =IF(AND(ISBLANK(A16),ISBLANK(B16),ISBLANK(C16)),"",IF(OR(ISBLANK(A16),ISBLANK(B16),ISBLANK(C16)),"-",LEN(Tableau4[[#This Row],[Colonne9]]))) | I16: =IF(AND(ISBLANK(A16),ISBLANK(B16),ISBLANK(C16)),"",IF(OR(ISBLANK(A16),ISBLANK(B16),ISBLANK(C16)),"à compléter",UPPER(LOOKUP(A16,BIB!A:A,BIB!B:B)&LOOKUP(B16,'Type de table'!C:C,'Type de table'!B:B) &IF(COUNTIF('Objets de gestion'!C:C,F16)=0,"","_"&LOOKUP(F16,'Objets de gestion'!C:C,'Objets de gestion'!F:F)) &IF(COUNTIF('Objets de gestion'!C:C,E16)=0,"","_"&LOOKUP(E16,'Objets de gestion'!C:C,'Objets de gestion'!F:F)) &IF(COUNTIF('Objets de gestion'!C:C,D16)=0,"","_"&LOOKUP(D16,'Objets de gestion'!C:C,'Objets de gestion'!F:F)) &IF(COUNTIF('Objets de gestion'!C:C,C16)=0,"","_"&LOOKUP(C16,'Objets de gestion'!C:C,'Objets de gestion'!F:F)) ))) | J16: =IF(AND(ISBLANK(A16),ISBLANK(B16),ISBLANK(C16)),"",IF(OR(ISBLANK(A16),ISBLANK(B16),ISBLANK(C16)),"-", LOOKUP(B16,'Type de table'!C:C,'Type de table'!E:E) &IF(ISBLANK(C16),""," "&C16) &IF(ISBLANK(D16),""," "&D16) &IF(ISBLANK(E16),""," "&E16) &IF(ISBLANK(F16),""," "&F16) )) | K16: =IF(AND(ISBLANK(A16),ISBLANK(B16),ISBLANK(C16)),"",IF(OR(ISBLANK(A16),ISBLANK(B16),ISBLANK(C16)),"-", LOOKUP(B16,'Type de table'!C:C,'Type de table'!F:F) &IF(ISBLANK(C16),""," "&LOOKUP(C16,'Objets de gestion'!C:C,'Objets de gestion'!E:E)) &IF(ISBLANK(D16),""," "&LOOKUP(D16,'Objets de gestion'!C:C,'Objets de gestion'!E:E)) &IF(ISBLANK(E16),""," "&LOOKUP(E16,'Objets de gestion'!C:C,'Objets de gestion'!E:E)) &IF(ISBLANK(F16),""," "&LOOKUP(F16,'Objets de gestion'!C:C,'Objets de gestion'!E:E)) )) | L16: =IF(AND(ISBLANK(A16),ISBLANK(B16),ISBLANK(C16)),"",IF(OR(ISBLANK(A16),ISBLANK(B16),ISBLANK(C16)),"-",B16))
G17: =IF(ISBLANK(A17),"",LOOKUP(A17,BIB!A:A,BIB!C:C)) | H17: =IF(AND(ISBLANK(A17),ISBLANK(B17),ISBLANK(C17)),"",IF(OR(ISBLANK(A17),ISBLANK(B17),ISBLANK(C17)),"-",LEN(Tableau4[[#This Row],[Colonne9]]))) | I17: =IF(AND(ISBLANK(A17),ISBLANK(B17),ISBLANK(C17)),"",IF(OR(ISBLANK(A17),ISBLANK(B17),ISBLANK(C17)),"à compléter",UPPER(LOOKUP(A17,BIB!A:A,BIB!B:B)&LOOKUP(B17,'Type de table'!C:C,'Type de table'!B:B) &IF(COUNTIF('Objets de gestion'!C:C,F17)=0,"","_"&LOOKUP(F17,'Objets de gestion'!C:C,'Objets de gestion'!F:F)) &IF(COUNTIF('Objets de gestion'!C:C,E17)=0,"","_"&LOOKUP(E17,'Objets de gestion'!C:C,'Objets de gestion'!F:F)) &IF(COUNTIF('Objets de gestion'!C:C,D17)=0,"","_"&LOOKUP(D17,'Objets de gestion'!C:C,'Objets de gestion'!F:F)) &IF(COUNTIF('Objets de gestion'!C:C,C17)=0,"","_"&LOOKUP(C17,'Objets de gestion'!C:C,'Objets de gestion'!F:F)) ))) | J17: =IF(AND(ISBLANK(A17),ISBLANK(B17),ISBLANK(C17)),"",IF(OR(ISBLANK(A17),ISBLANK(B17),ISBLANK(C17)),"-", LOOKUP(B17,'Type de table'!C:C,'Type de table'!E:E) &IF(ISBLANK(C17),""," "&C17) &IF(ISBLANK(D17),""," "&D17) &IF(ISBLANK(E17),""," "&E17) &IF(ISBLANK(F17),""," "&F17) )) | K17: =IF(AND(ISBLANK(A17),ISBLANK(B17),ISBLANK(C17)),"",IF(OR(ISBLANK(A17),ISBLANK(B17),ISBLANK(C17)),"-", LOOKUP(B17,'Type de table'!C:C,'Type de table'!F:F) &IF(ISBLANK(C17),""," "&LOOKUP(C17,'Objets de gestion'!C:C,'Objets de gestion'!E:E)) &IF(ISBLANK(D17),""," "&LOOKUP(D17,'Objets de gestion'!C:C,'Objets de gestion'!E:E)) &IF(ISBLANK(E17),""," "&LOOKUP(E17,'Objets de gestion'!C:C,'Objets de gestion'!E:E)) &IF(ISBLANK(F17),""," "&LOOKUP(F17,'Objets de gestion'!C:C,'Objets de gestion'!E:E)) )) | L17: =IF(AND(ISBLANK(A17),ISBLANK(B17),ISBLANK(C17)),"",IF(OR(ISBLANK(A17),ISBLANK(B17),ISBLANK(C17)),"-",B17))
G18: =IF(ISBLANK(A18),"",LOOKUP(A18,BIB!A:A,BIB!C:C)) | H18: =IF(AND(ISBLANK(A18),ISBLANK(B18),ISBLANK(C18)),"",IF(OR(ISBLANK(A18),ISBLANK(B18),ISBLANK(C18)),"-",LEN(Tableau4[[#This Row],[Colonne9]]))) | I18: =IF(AND(ISBLANK(A18),ISBLANK(B18),ISBLANK(C18)),"",IF(OR(ISBLANK(A18),ISBLANK(B18),ISBLANK(C18)),"à compléter",UPPER(LOOKUP(A18,BIB!A:A,BIB!B:B)&LOOKUP(B18,'Type de table'!C:C,'Type de table'!B:B) &IF(COUNTIF('Objets de gestion'!C:C,F18)=0,"","_"&LOOKUP(F18,'Objets de gestion'!C:C,'Objets de gestion'!F:F)) &IF(COUNTIF('Objets de gestion'!C:C,E18)=0,"","_"&LOOKUP(E18,'Objets de gestion'!C:C,'Objets de gestion'!F:F)) &IF(COUNTIF('Objets de gestion'!C:C,D18)=0,"","_"&LOOKUP(D18,'Objets de gestion'!C:C,'Objets de gestion'!F:F)) &IF(COUNTIF('Objets de gestion'!C:C,C18)=0,"","_"&LOOKUP(C18,'Objets de gestion'!C:C,'Objets de gestion'!F:F)) ))) | J18: =IF(AND(ISBLANK(A18),ISBLANK(B18),ISBLANK(C18)),"",IF(OR(ISBLANK(A18),ISBLANK(B18),ISBLANK(C18)),"-", LOOKUP(B18,'Type de table'!C:C,'Type de table'!E:E) &IF(ISBLANK(C18),""," "&C18) &IF(ISBLANK(D18),""," "&D18) &IF(ISBLANK(E18),""," "&E18) &IF(ISBLANK(F18),""," "&F18) )) | K18: =IF(AND(ISBLANK(A18),ISBLANK(B18),ISBLANK(C18)),"",IF(OR(ISBLANK(A18),ISBLANK(B18),ISBLANK(C18)),"-", LOOKUP(B18,'Type de table'!C:C,'Type de table'!F:F) &IF(ISBLANK(C18),""," "&LOOKUP(C18,'Objets de gestion'!C:C,'Objets de gestion'!E:E)) &IF(ISBLANK(D18),""," "&LOOKUP(D18,'Objets de gestion'!C:C,'Objets de gestion'!E:E)) &IF(ISBLANK(E18),""," "&LOOKUP(E18,'Objets de gestion'!C:C,'Objets de gestion'!E:E)) &IF(ISBLANK(F18),""," "&LOOKUP(F18,'Objets de gestion'!C:C,'Objets de gestion'!E:E)) )) | L18: =IF(AND(ISBLANK(A18),ISBLANK(B18),ISBLANK(C18)),"",IF(OR(ISBLANK(A18),ISBLANK(B18),ISBLANK(C18)),"-",B18))
G19: =IF(ISBLANK(A19),"",LOOKUP(A19,BIB!A:A,BIB!C:C)) | H19: =IF(AND(ISBLANK(A19),ISBLANK(B19),ISBLANK(C19)),"",IF(OR(ISBLANK(A19),ISBLANK(B19),ISBLANK(C19)),"-",LEN(Tableau4[[#This Row],[Colonne9]]))) | I19: =IF(AND(ISBLANK(A19),ISBLANK(B19),ISBLANK(C19)),"",IF(OR(ISBLANK(A19),ISBLANK(B19),ISBLANK(C19)),"à compléter",UPPER(LOOKUP(A19,BIB!A:A,BIB!B:B)&LOOKUP(B19,'Type de table'!C:C,'Type de table'!B:B) &IF(COUNTIF('Objets de gestion'!C:C,F19)=0,"","_"&LOOKUP(F19,'Objets de gestion'!C:C,'Objets de gestion'!F:F)) &IF(COUNTIF('Objets de gestion'!C:C,E19)=0,"","_"&LOOKUP(E19,'Objets de gestion'!C:C,'Objets de gestion'!F:F)) &IF(COUNTIF('Objets de gestion'!C:C,D19)=0,"","_"&LOOKUP(D19,'Objets de gestion'!C:C,'Objets de gestion'!F:F)) &IF(COUNTIF('Objets de gestion'!C:C,C19)=0,"","_"&LOOKUP(C19,'Objets de gestion'!C:C,'Objets de gestion'!F:F)) ))) | J19: =IF(AND(ISBLANK(A19),ISBLANK(B19),ISBLANK(C19)),"",IF(OR(ISBLANK(A19),ISBLANK(B19),ISBLANK(C19)),"-", LOOKUP(B19,'Type de table'!C:C,'Type de table'!E:E) &IF(ISBLANK(C19),""," "&C19) &IF(ISBLANK(D19),""," "&D19) &IF(ISBLANK(E19),""," "&E19) &IF(ISBLANK(F19),""," "&F19) )) | K19: =IF(AND(ISBLANK(A19),ISBLANK(B19),ISBLANK(C19)),"",IF(OR(ISBLANK(A19),ISBLANK(B19),ISBLANK(C19)),"-", LOOKUP(B19,'Type de table'!C:C,'Type de table'!F:F) &IF(ISBLANK(C19),""," "&LOOKUP(C19,'Objets de gestion'!C:C,'Objets de gestion'!E:E)) &IF(ISBLANK(D19),""," "&LOOKUP(D19,'Objets de gestion'!C:C,'Objets de gestion'!E:E)) &IF(ISBLANK(E19),""," "&LOOKUP(E19,'Objets de gestion'!C:C,'Objets de gestion'!E:E)) &IF(ISBLANK(F19),""," "&LOOKUP(F19,'Objets de gestion'!C:C,'Objets de gestion'!E:E)) )) | L19: =IF(AND(ISBLANK(A19),ISBLANK(B19),ISBLANK(C19)),"",IF(OR(ISBLANK(A19),ISBLANK(B19),ISBLANK(C19)),"-",B19))
G20: =IF(ISBLANK(A20),"",LOOKUP(A20,BIB!A:A,BIB!C:C)) | H20: =IF(AND(ISBLANK(A20),ISBLANK(B20),ISBLANK(C20)),"",IF(OR(ISBLANK(A20),ISBLANK(B20),ISBLANK(C20)),"-",LEN(Tableau4[[#This Row],[Colonne9]]))) | I20: =IF(AND(ISBLANK(A20),ISBLANK(B20),ISBLANK(C20)),"",IF(OR(ISBLANK(A20),ISBLANK(B20),ISBLANK(C20)),"à compléter",UPPER(LOOKUP(A20,BIB!A:A,BIB!B:B)&LOOKUP(B20,'Type de table'!C:C,'Type de table'!B:B) &IF(COUNTIF('Objets de gestion'!C:C,F20)=0,"","_"&LOOKUP(F20,'Objets de gestion'!C:C,'Objets de gestion'!F:F)) &IF(COUNTIF('Objets de gestion'!C:C,E20)=0,"","_"&LOOKUP(E20,'Objets de gestion'!C:C,'Objets de gestion'!F:F)) &IF(COUNTIF('Objets de gestion'!C:C,D20)=0,"","_"&LOOKUP(D20,'Objets de gestion'!C:C,'Objets de gestion'!F:F)) &IF(COUNTIF('Objets de gestion'!C:C,C20)=0,"","_"&LOOKUP(C20,'Objets de gestion'!C:C,'Objets de gestion'!F:F)) ))) | J20: =IF(AND(ISBLANK(A20),ISBLANK(B20),ISBLANK(C20)),"",IF(OR(ISBLANK(A20),ISBLANK(B20),ISBLANK(C20)),"-", LOOKUP(B20,'Type de table'!C:C,'Type de table'!E:E) &IF(ISBLANK(C20),""," "&C20) &IF(ISBLANK(D20),""," "&D20) &IF(ISBLANK(E20),""," "&E20) &IF(ISBLANK(F20),""," "&F20) )) | K20: =IF(AND(ISBLANK(A20),ISBLANK(B20),ISBLANK(C20)),"",IF(OR(ISBLANK(A20),ISBLANK(B20),ISBLANK(C20)),"-", LOOKUP(B20,'Type de table'!C:C,'Type de table'!F:F) &IF(ISBLANK(C20),""," "&LOOKUP(C20,'Objets de gestion'!C:C,'Objets de gestion'!E:E)) &IF(ISBLANK(D20),""," "&LOOKUP(D20,'Objets de gestion'!C:C,'Objets de gestion'!E:E)) &IF(ISBLANK(E20),""," "&LOOKUP(E20,'Objets de gestion'!C:C,'Objets de gestion'!E:E)) &IF(ISBLANK(F20),""," "&LOOKUP(F20,'Objets de gestion'!C:C,'Objets de gestion'!E:E)) )) | L20: =IF(AND(ISBLANK(A20),ISBLANK(B20),ISBLANK(C20)),"",IF(OR(ISBLANK(A20),ISBLANK(B20),ISBLANK(C20)),"-",B20))
G21: =IF(ISBLANK(A21),"",LOOKUP(A21,BIB!A:A,BIB!C:C)) | H21: =IF(AND(ISBLANK(A21),ISBLANK(B21),ISBLANK(C21)),"",IF(OR(ISBLANK(A21),ISBLANK(B21),ISBLANK(C21)),"-",LEN(Tableau4[[#This Row],[Colonne9]]))) | I21: =IF(AND(ISBLANK(A21),ISBLANK(B21),ISBLANK(C21)),"",IF(OR(ISBLANK(A21),ISBLANK(B21),ISBLANK(C21)),"à compléter",UPPER(LOOKUP(A21,BIB!A:A,BIB!B:B)&LOOKUP(B21,'Type de table'!C:C,'Type de table'!B:B) &IF(COUNTIF('Objets de gestion'!C:C,F21)=0,"","_"&LOOKUP(F21,'Objets de gestion'!C:C,'Objets de gestion'!F:F)) &IF(COUNTIF('Objets de gestion'!C:C,E21)=0,"","_"&LOOKUP(E21,'Objets de gestion'!C:C,'Objets de gestion'!F:F)) &IF(COUNTIF('Objets de gestion'!C:C,D21)=0,"","_"&LOOKUP(D21,'Objets de gestion'!C:C,'Objets de gestion'!F:F)) &IF(COUNTIF('Objets de gestion'!C:C,C21)=0,"","_"&LOOKUP(C21,'Objets de gestion'!C:C,'Objets de gestion'!F:F)) ))) | J21: =IF(AND(ISBLANK(A21),ISBLANK(B21),ISBLANK(C21)),"",IF(OR(ISBLANK(A21),ISBLANK(B21),ISBLANK(C21)),"-", LOOKUP(B21,'Type de table'!C:C,'Type de table'!E:E) &IF(ISBLANK(C21),""," "&C21) &IF(ISBLANK(D21),""," "&D21) &IF(ISBLANK(E21),""," "&E21) &IF(ISBLANK(F21),""," "&F21) )) | K21: =IF(AND(ISBLANK(A21),ISBLANK(B21),ISBLANK(C21)),"",IF(OR(ISBLANK(A21),ISBLANK(B21),ISBLANK(C21)),"-", LOOKUP(B21,'Type de table'!C:C,'Type de table'!F:F) &IF(ISBLANK(C21),""," "&LOOKUP(C21,'Objets de gestion'!C:C,'Objets de gestion'!E:E)) &IF(ISBLANK(D21),""," "&LOOKUP(D21,'Objets de gestion'!C:C,'Objets de gestion'!E:E)) &IF(ISBLANK(E21),""," "&LOOKUP(E21,'Objets de gestion'!C:C,'Objets de gestion'!E:E)) &IF(ISBLANK(F21),""," "&LOOKUP(F21,'Objets de gestion'!C:C,'Objets de gestion'!E:E)) )) | L21: =IF(AND(ISBLANK(A21),ISBLANK(B21),ISBLANK(C21)),"",IF(OR(ISBLANK(A21),ISBLANK(B21),ISBLANK(C21)),"-",B21))
G22: =IF(ISBLANK(A22),"",LOOKUP(A22,BIB!A:A,BIB!C:C)) | H22: =IF(AND(ISBLANK(A22),ISBLANK(B22),ISBLANK(C22)),"",IF(OR(ISBLANK(A22),ISBLANK(B22),ISBLANK(C22)),"-",LEN(Tableau4[[#This Row],[Colonne9]]))) | I22: =IF(AND(ISBLANK(A22),ISBLANK(B22),ISBLANK(C22)),"",IF(OR(ISBLANK(A22),ISBLANK(B22),ISBLANK(C22)),"à compléter",UPPER(LOOKUP(A22,BIB!A:A,BIB!B:B)&LOOKUP(B22,'Type de table'!C:C,'Type de table'!B:B) &IF(COUNTIF('Objets de gestion'!C:C,F22)=0,"","_"&LOOKUP(F22,'Objets de gestion'!C:C,'Objets de gestion'!F:F)) &IF(COUNTIF('Objets de gestion'!C:C,E22)=0,"","_"&LOOKUP(E22,'Objets de gestion'!C:C,'Objets de gestion'!F:F)) &IF(COUNTIF('Objets de gestion'!C:C,D22)=0,"","_"&LOOKUP(D22,'Objets de gestion'!C:C,'Objets de gestion'!F:F)) &IF(COUNTIF('Objets de gestion'!C:C,C22)=0,"","_"&LOOKUP(C22,'Objets de gestion'!C:C,'Objets de gestion'!F:F)) ))) | J22: =IF(AND(ISBLANK(A22),ISBLANK(B22),ISBLANK(C22)),"",IF(OR(ISBLANK(A22),ISBLANK(B22),ISBLANK(C22)),"-", LOOKUP(B22,'Type de table'!C:C,'Type de table'!E:E) &IF(ISBLANK(C22),""," "&C22) &IF(ISBLANK(D22),""," "&D22) &IF(ISBLANK(E22),""," "&E22) &IF(ISBLANK(F22),""," "&F22) )) | K22: =IF(AND(ISBLANK(A22),ISBLANK(B22),ISBLANK(C22)),"",IF(OR(ISBLANK(A22),ISBLANK(B22),ISBLANK(C22)),"-", LOOKUP(B22,'Type de table'!C:C,'Type de table'!F:F) &IF(ISBLANK(C22),""," "&LOOKUP(C22,'Objets de gestion'!C:C,'Objets de gestion'!E:E)) &IF(ISBLANK(D22),""," "&LOOKUP(D22,'Objets de gestion'!C:C,'Objets de gestion'!E:E)) &IF(ISBLANK(E22),""," "&LOOKUP(E22,'Objets de gestion'!C:C,'Objets de gestion'!E:E)) &IF(ISBLANK(F22),""," "&LOOKUP(F22,'Objets de gestion'!C:C,'Objets de gestion'!E:E)) )) | L22: =IF(AND(ISBLANK(A22),ISBLANK(B22),ISBLANK(C22)),"",IF(OR(ISBLANK(A22),ISBLANK(B22),ISBLANK(C22)),"-",B22))
G23: =IF(ISBLANK(A23),"",LOOKUP(A23,BIB!A:A,BIB!C:C)) | H23: =IF(AND(ISBLANK(A23),ISBLANK(B23),ISBLANK(C23)),"",IF(OR(ISBLANK(A23),ISBLANK(B23),ISBLANK(C23)),"-",LEN(Tableau4[[#This Row],[Colonne9]]))) | I23: =IF(AND(ISBLANK(A23),ISBLANK(B23),ISBLANK(C23)),"",IF(OR(ISBLANK(A23),ISBLANK(B23),ISBLANK(C23)),"à compléter",UPPER(LOOKUP(A23,BIB!A:A,BIB!B:B)&LOOKUP(B23,'Type de table'!C:C,'Type de table'!B:B) &IF(COUNTIF('Objets de gestion'!C:C,F23)=0,"","_"&LOOKUP(F23,'Objets de gestion'!C:C,'Objets de gestion'!F:F)) &IF(COUNTIF('Objets de gestion'!C:C,E23)=0,"","_"&LOOKUP(E23,'Objets de gestion'!C:C,'Objets de gestion'!F:F)) &IF(COUNTIF('Objets de gestion'!C:C,D23)=0,"","_"&LOOKUP(D23,'Objets de gestion'!C:C,'Objets de gestion'!F:F)) &IF(COUNTIF('Objets de gestion'!C:C,C23)=0,"","_"&LOOKUP(C23,'Objets de gestion'!C:C,'Objets de gestion'!F:F)) ))) | J23: =IF(AND(ISBLANK(A23),ISBLANK(B23),ISBLANK(C23)),"",IF(OR(ISBLANK(A23),ISBLANK(B23),ISBLANK(C23)),"-", LOOKUP(B23,'Type de table'!C:C,'Type de table'!E:E) &IF(ISBLANK(C23),""," "&C23) &IF(ISBLANK(D23),""," "&D23) &IF(ISBLANK(E23),""," "&E23) &IF(ISBLANK(F23),""," "&F23) )) | K23: =IF(AND(ISBLANK(A23),ISBLANK(B23),ISBLANK(C23)),"",IF(OR(ISBLANK(A23),ISBLANK(B23),ISBLANK(C23)),"-", LOOKUP(B23,'Type de table'!C:C,'Type de table'!F:F) &IF(ISBLANK(C23),""," "&LOOKUP(C23,'Objets de gestion'!C:C,'Objets de gestion'!E:E)) &IF(ISBLANK(D23),""," "&LOOKUP(D23,'Objets de gestion'!C:C,'Objets de gestion'!E:E)) &IF(ISBLANK(E23),""," "&LOOKUP(E23,'Objets de gestion'!C:C,'Objets de gestion'!E:E)) &IF(ISBLANK(F23),""," "&LOOKUP(F23,'Objets de gestion'!C:C,'Objets de gestion'!E:E)) )) | L23: =IF(AND(ISBLANK(A23),ISBLANK(B23),ISBLANK(C23)),"",IF(OR(ISBLANK(A23),ISBLANK(B23),ISBLANK(C23)),"-",B23))
G24: =IF(ISBLANK(A24),"",LOOKUP(A24,BIB!A:A,BIB!C:C)) | H24: =IF(AND(ISBLANK(A24),ISBLANK(B24),ISBLANK(C24)),"",IF(OR(ISBLANK(A24),ISBLANK(B24),ISBLANK(C24)),"-",LEN(Tableau4[[#This Row],[Colonne9]]))) | I24: =IF(AND(ISBLANK(A24),ISBLANK(B24),ISBLANK(C24)),"",IF(OR(ISBLANK(A24),ISBLANK(B24),ISBLANK(C24)),"à compléter",UPPER(LOOKUP(A24,BIB!A:A,BIB!B:B)&LOOKUP(B24,'Type de table'!C:C,'Type de table'!B:B) &IF(COUNTIF('Objets de gestion'!C:C,F24)=0,"","_"&LOOKUP(F24,'Objets de gestion'!C:C,'Objets de gestion'!F:F)) &IF(COUNTIF('Objets de gestion'!C:C,E24)=0,"","_"&LOOKUP(E24,'Objets de gestion'!C:C,'Objets de gestion'!F:F)) &IF(COUNTIF('Objets de gestion'!C:C,D24)=0,"","_"&LOOKUP(D24,'Objets de gestion'!C:C,'Objets de gestion'!F:F)) &IF(COUNTIF('Objets de gestion'!C:C,C24)=0,"","_"&LOOKUP(C24,'Objets de gestion'!C:C,'Objets de gestion'!F:F)) ))) | J24: =IF(AND(ISBLANK(A24),ISBLANK(B24),ISBLANK(C24)),"",IF(OR(ISBLANK(A24),ISBLANK(B24),ISBLANK(C24)),"-", LOOKUP(B24,'Type de table'!C:C,'Type de table'!E:E) &IF(ISBLANK(C24),""," "&C24) &IF(ISBLANK(D24),""," "&D24) &IF(ISBLANK(E24),""," "&E24) &IF(ISBLANK(F24),""," "&F24) )) | K24: =IF(AND(ISBLANK(A24),ISBLANK(B24),ISBLANK(C24)),"",IF(OR(ISBLANK(A24),ISBLANK(B24),ISBLANK(C24)),"-", LOOKUP(B24,'Type de table'!C:C,'Type de table'!F:F) &IF(ISBLANK(C24),""," "&LOOKUP(C24,'Objets de gestion'!C:C,'Objets de gestion'!E:E)) &IF(ISBLANK(D24),""," "&LOOKUP(D24,'Objets de gestion'!C:C,'Objets de gestion'!E:E)) &IF(ISBLANK(E24),""," "&LOOKUP(E24,'Objets de gestion'!C:C,'Objets de gestion'!E:E)) &IF(ISBLANK(F24),""," "&LOOKUP(F24,'Objets de gestion'!C:C,'Objets de gestion'!E:E)) )) | L24: =IF(AND(ISBLANK(A24),ISBLANK(B24),ISBLANK(C24)),"",IF(OR(ISBLANK(A24),ISBLANK(B24),ISBLANK(C24)),"-",B24))
G25: =IF(ISBLANK(A25),"",LOOKUP(A25,BIB!A:A,BIB!C:C)) | H25: =IF(AND(ISBLANK(A25),ISBLANK(B25),ISBLANK(C25)),"",IF(OR(ISBLANK(A25),ISBLANK(B25),ISBLANK(C25)),"-",LEN(Tableau4[[#This Row],[Colonne9]]))) | I25: =IF(AND(ISBLANK(A25),ISBLANK(B25),ISBLANK(C25)),"",IF(OR(ISBLANK(A25),ISBLANK(B25),ISBLANK(C25)),"à compléter",UPPER(LOOKUP(A25,BIB!A:A,BIB!B:B)&LOOKUP(B25,'Type de table'!C:C,'Type de table'!B:B) &IF(COUNTIF('Objets de gestion'!C:C,F25)=0,"","_"&LOOKUP(F25,'Objets de gestion'!C:C,'Objets de gestion'!F:F)) &IF(COUNTIF('Objets de gestion'!C:C,E25)=0,"","_"&LOOKUP(E25,'Objets de gestion'!C:C,'Objets de gestion'!F:F)) &IF(COUNTIF('Objets de gestion'!C:C,D25)=0,"","_"&LOOKUP(D25,'Objets de gestion'!C:C,'Objets de gestion'!F:F)) &IF(COUNTIF('Objets de gestion'!C:C,C25)=0,"","_"&LOOKUP(C25,'Objets de gestion'!C:C,'Objets de gestion'!F:F)) ))) | J25: =IF(AND(ISBLANK(A25),ISBLANK(B25),ISBLANK(C25)),"",IF(OR(ISBLANK(A25),ISBLANK(B25),ISBLANK(C25)),"-", LOOKUP(B25,'Type de table'!C:C,'Type de table'!E:E) &IF(ISBLANK(C25),""," "&C25) &IF(ISBLANK(D25),""," "&D25) &IF(ISBLANK(E25),""," "&E25) &IF(ISBLANK(F25),""," "&F25) )) | K25: =IF(AND(ISBLANK(A25),ISBLANK(B25),ISBLANK(C25)),"",IF(OR(ISBLANK(A25),ISBLANK(B25),ISBLANK(C25)),"-", LOOKUP(B25,'Type de table'!C:C,'Type de table'!F:F) &IF(ISBLANK(C25),""," "&LOOKUP(C25,'Objets de gestion'!C:C,'Objets de gestion'!E:E)) &IF(ISBLANK(D25),""," "&LOOKUP(D25,'Objets de gestion'!C:C,'Objets de gestion'!E:E)) &IF(ISBLANK(E25),""," "&LOOKUP(E25,'Objets de gestion'!C:C,'Objets de gestion'!E:E)) &IF(ISBLANK(F25),""," "&LOOKUP(F25,'Objets de gestion'!C:C,'Objets de gestion'!E:E)) )) | L25: =IF(AND(ISBLANK(A25),ISBLANK(B25),ISBLANK(C25)),"",IF(OR(ISBLANK(A25),ISBLANK(B25),ISBLANK(C25)),"-",B25))
G26: =IF(ISBLANK(A26),"",LOOKUP(A26,BIB!A:A,BIB!C:C)) | H26: =IF(AND(ISBLANK(A26),ISBLANK(B26),ISBLANK(C26)),"",IF(OR(ISBLANK(A26),ISBLANK(B26),ISBLANK(C26)),"-",LEN(Tableau4[[#This Row],[Colonne9]]))) | I26: =IF(AND(ISBLANK(A26),ISBLANK(B26),ISBLANK(C26)),"",IF(OR(ISBLANK(A26),ISBLANK(B26),ISBLANK(C26)),"à compléter",UPPER(LOOKUP(A26,BIB!A:A,BIB!B:B)&LOOKUP(B26,'Type de table'!C:C,'Type de table'!B:B) &IF(COUNTIF('Objets de gestion'!C:C,F26)=0,"","_"&LOOKUP(F26,'Objets de gestion'!C:C,'Objets de gestion'!F:F)) &IF(COUNTIF('Objets de gestion'!C:C,E26)=0,"","_"&LOOKUP(E26,'Objets de gestion'!C:C,'Objets de gestion'!F:F)) &IF(COUNTIF('Objets de gestion'!C:C,D26)=0,"","_"&LOOKUP(D26,'Objets de gestion'!C:C,'Objets de gestion'!F:F)) &IF(COUNTIF('Objets de gestion'!C:C,C26)=0,"","_"&LOOKUP(C26,'Objets de gestion'!C:C,'Objets de gestion'!F:F)) ))) | J26: =IF(AND(ISBLANK(A26),ISBLANK(B26),ISBLANK(C26)),"",IF(OR(ISBLANK(A26),ISBLANK(B26),ISBLANK(C26)),"-", LOOKUP(B26,'Type de table'!C:C,'Type de table'!E:E) &IF(ISBLANK(C26),""," "&C26) &IF(ISBLANK(D26),""," "&D26) &IF(ISBLANK(E26),""," "&E26) &IF(ISBLANK(F26),""," "&F26) )) | K26: =IF(AND(ISBLANK(A26),ISBLANK(B26),ISBLANK(C26)),"",IF(OR(ISBLANK(A26),ISBLANK(B26),ISBLANK(C26)),"-", LOOKUP(B26,'Type de table'!C:C,'Type de table'!F:F) &IF(ISBLANK(C26),""," "&LOOKUP(C26,'Objets de gestion'!C:C,'Objets de gestion'!E:E)) &IF(ISBLANK(D26),""," "&LOOKUP(D26,'Objets de gestion'!C:C,'Objets de gestion'!E:E)) &IF(ISBLANK(E26),""," "&LOOKUP(E26,'Objets de gestion'!C:C,'Objets de gestion'!E:E)) &IF(ISBLANK(F26),""," "&LOOKUP(F26,'Objets de gestion'!C:C,'Objets de gestion'!E:E)) )) | L26: =IF(AND(ISBLANK(A26),ISBLANK(B26),ISBLANK(C26)),"",IF(OR(ISBLANK(A26),ISBLANK(B26),ISBLANK(C26)),"-",B26))
G27: =IF(ISBLANK(A27),"",LOOKUP(A27,BIB!A:A,BIB!C:C)) | H27: =IF(AND(ISBLANK(A27),ISBLANK(B27),ISBLANK(C27)),"",IF(OR(ISBLANK(A27),ISBLANK(B27),ISBLANK(C27)),"-",LEN(Tableau4[[#This Row],[Colonne9]]))) | I27: =IF(AND(ISBLANK(A27),ISBLANK(B27),ISBLANK(C27)),"",IF(OR(ISBLANK(A27),ISBLANK(B27),ISBLANK(C27)),"à compléter",UPPER(LOOKUP(A27,BIB!A:A,BIB!B:B)&LOOKUP(B27,'Type de table'!C:C,'Type de table'!B:B) &IF(COUNTIF('Objets de gestion'!C:C,F27)=0,"","_"&LOOKUP(F27,'Objets de gestion'!C:C,'Objets de gestion'!F:F)) &IF(COUNTIF('Objets de gestion'!C:C,E27)=0,"","_"&LOOKUP(E27,'Objets de gestion'!C:C,'Objets de gestion'!F:F)) &IF(COUNTIF('Objets de gestion'!C:C,D27)=0,"","_"&LOOKUP(D27,'Objets de gestion'!C:C,'Objets de gestion'!F:F)) &IF(COUNTIF('Objets de gestion'!C:C,C27)=0,"","_"&LOOKUP(C27,'Objets de gestion'!C:C,'Objets de gestion'!F:F)) ))) | J27: =IF(AND(ISBLANK(A27),ISBLANK(B27),ISBLANK(C27)),"",IF(OR(ISBLANK(A27),ISBLANK(B27),ISBLANK(C27)),"-", LOOKUP(B27,'Type de table'!C:C,'Type de table'!E:E) &IF(ISBLANK(C27),""," "&C27) &IF(ISBLANK(D27),""," "&D27) &IF(ISBLANK(E27),""," "&E27) &IF(ISBLANK(F27),""," "&F27) )) | K27: =IF(AND(ISBLANK(A27),ISBLANK(B27),ISBLANK(C27)),"",IF(OR(ISBLANK(A27),ISBLANK(B27),ISBLANK(C27)),"-", LOOKUP(B27,'Type de table'!C:C,'Type de table'!F:F) &IF(ISBLANK(C27),""," "&LOOKUP(C27,'Objets de gestion'!C:C,'Objets de gestion'!E:E)) &IF(ISBLANK(D27),""," "&LOOKUP(D27,'Objets de gestion'!C:C,'Objets de gestion'!E:E)) &IF(ISBLANK(E27),""," "&LOOKUP(E27,'Objets de gestion'!C:C,'Objets de gestion'!E:E)) &IF(ISBLANK(F27),""," "&LOOKUP(F27,'Objets de gestion'!C:C,'Objets de gestion'!E:E)) )) | L27: =IF(AND(ISBLANK(A27),ISBLANK(B27),ISBLANK(C27)),"",IF(OR(ISBLANK(A27),ISBLANK(B27),ISBLANK(C27)),"-",B27))
... G74: =IF(ISBLANK(A74),"",LOOKUP(A74,BIB!A:A,BIB!C:C)) | H74: =IF(AND(ISBLANK(A74),ISBLANK(B74),ISBLANK(C74)),"",IF(OR(ISBLANK(A74),ISBLANK(B74),ISBLANK(C74)),"-",LEN(Tableau4[[#This Row],[Colonne9]]))) | I74: =IF(AND(ISBLANK(A74),ISBLANK(B74),ISBLANK(C74)),"",IF(OR(ISBLANK(A74),ISBLANK(B74),ISBLANK(C74)),"à compléter",UPPER(LOOKUP(A74,BIB!A:A,BIB!B:B)&LOOKUP(B74,'Type de table'!C:C,'Type de table'!B:B) &IF(COUNTIF('Objets de gestion'!C:C,F74)=0,"","_"&LOOKUP(F74,'Objets de gestion'!C:C,'Objets de gestion'!F:F)) &IF(COUNTIF('Objets de gestion'!C:C,E74)=0,"","_"&LOOKUP(E74,'Objets de gestion'!C:C,'Objets de gestion'!F:F)) &IF(COUNTIF('Objets de gestion'!C:C,D74)=0,"","_"&LOOKUP(D74,'Objets de gestion'!C:C,'Objets de gestion'!F:F)) &IF(COUNTIF('Objets de gestion'!C:C,C74)=0,"","_"&LOOKUP(C74,'Objets de gestion'!C:C,'Objets de gestion'!F:F)) ))) | J74: =IF(AND(ISBLANK(A74),ISBLANK(B74),ISBLANK(C74)),"",IF(OR(ISBLANK(A74),ISBLANK(B74),ISBLANK(C74)),"-", LOOKUP(B74,'Type de table'!C:C,'Type de table'!E:E) &IF(ISBLANK(C74),""," "&C74) &IF(ISBLANK(D74),""," "&D74) &IF(ISBLANK(E74),""," "&E74) &IF(ISBLANK(F74),""," "&F74) )) | K74: =IF(AND(ISBLANK(A74),ISBLANK(B74),ISBLANK(C74)),"",IF(OR(ISBLANK(A74),ISBLANK(B74),ISBLANK(C74)),"-", LOOKUP(B74,'Type de table'!C:C,'Type de table'!F:F) &IF(ISBLANK(C74),""," "&LOOKUP(C74,'Objets de gestion'!C:C,'Objets de gestion'!E:E)) &IF(ISBLANK(D74),""," "&LOOKUP(D74,'Objets de gestion'!C:C,'Objets de gestion'!E:E)) &IF(ISBLANK(E74),""," "&LOOKUP(E74,'Objets de gestion'!C:C,'Objets de gestion'!E:E)) &IF(ISBLANK(F74),""," "&LOOKUP(F74,'Objets de gestion'!C:C,'Objets de gestion'!E:E)) )) | L74: =IF(AND(ISBLANK(A74),ISBLANK(B74),ISBLANK(C74)),"",IF(OR(ISBLANK(A74),ISBLANK(B74),ISBLANK(C74)),"-",B74))

Sheet Champs
A1: Nom du BIB | B1: Type de champ | C1: Nature | D1: article 1 | E1: Objet de gestion 1 | F1: article 2 | G1: Objet de gestion 2 | H1: article 3 | I1: Objet de gestion 3 | J1: article 4 | K1: Objet de gestion 4 | L1: Ordre trigramme | M1: Nb car | N1: Code | O1: Nom français | P1: Nom anglais | Q1: Type de données | R1: Périmètre
M2: =IF(AND(ISBLANK(A2),ISBLANK(B2),ISBLANK(E2),ISBLANK(G2),ISBLANK(L2)),"",IF(OR(ISBLANK(A2),ISBLANK(B2),ISBLANK(E2),ISBLANK(G2),ISBLANK(L2)),"-",LEN(Tableau47[[#This Row],[Code]]))) | N2: =IF(AND(ISBLANK(A2),ISBLANK(B2),ISBLANK(C2),ISBLANK(E2),ISBLANK(L2)),"",IF(OR(ISBLANK(A2),ISBLANK(B2),ISBLANK(C2),ISBLANK(E2),ISBLANK(L2)),"à compléter", IF(L2="Normal", LOOKUP(B2,'Type de champ'!B:B,'Type de champ'!A:A) &IF(COUNTIF('Objets de gestion'!C:C,K2)=0,"","_"&LOOKUP(K2,'Objets de gestion'!C:C,'Objets de gestion'!F:F)) &IF(COUNTIF('Objets de gestion'!C:C,I2)=0,"","_"&LOOKUP(I2,'Objets de gestion'!C:C,'Objets de gestion'!F:F)) &IF(COUNTIF('Objets de gestion'!C:C,G2)=0,"","_"&LOOKUP(G2,'Objets de gestion'!C:C,'Objets de gestion'!F:F)) &IF(COUNTIF('Objets de gestion'!C:C,E2)=0,"","_"&LOOKUP(E2,'Objets de gestion'!C:C,'Objets de gestion'!F:F)) &IF(OR(C2="booléen",COUNTIF('Objets de gestion'!C:C,C2)=0),"","_"&LOOKUP(C2,'Objets de gestion'!C:C,'Objets de gestion'!F:F)), IF(L2="Forcé", LOOKUP(B2,'Type de champ'!B:B,'Type de champ'!A:A) &IF(COUNTIF('Objets de gestion'!C:C,E2)=0,"","_"&LOOKUP(E2,'Objets de gestion'!C:C,'Objets de gestion'!F:F)) &IF(COUNTIF('Objets de gestion'!C:C,G2)=0,"","_"&LOOKUP(G2,'Objets de gestion'!C:C,'Objets de gestion'!F:F)) &IF(COUNTIF('Objets de gestion'!C:C,I2)=0,"","_"&LOOKUP(I2,'Objets de gestion'!C:C,'Objets de gestion'!F:F)) &IF(COUNTIF('Objets de gestion'!C:C,K2)=0,"","_"&LOOKUP(K2,'Objets de gestion'!C:C,'Objets de gestion'!F:F)) &IF(OR(C2="booléen",COUNTIF('Objets de gestion'!C:C,C2)=0),"","_"&LOOKUP(C2,'Objets de gestion'!C:C,'Objets de gestion'!F:F)) )))) | O2: =IF(AND(ISBLANK(A2),ISBLANK(B2),ISBLANK(C2),ISBLANK(E2),ISBLANK(L2)),"",IF(OR(ISBLANK(A2),ISBLANK(B2),ISBLANK(C2),ISBLANK(E2),ISBLANK(L2)),"-", C2&" "&IF(ISBLANK(E2),"",D2&" "&E2&" ")&IF(ISBLANK(G2),"",F2&" "&G2&" ")&IF(ISBLANK(I2),"",H2&" "&I2&" ")&IF(ISBLANK(K2),"",J2&" "&K2&" "))) | P2: =IF(AND(ISBLANK(A2),ISBLANK(B2),ISBLANK(C2),ISBLANK(E2),ISBLANK(L2)),"",IF(OR(ISBLANK(A2),ISBLANK(B2),ISBLANK(C2),ISBLANK(E2),ISBLANK(L2)),"-", IF(ISBLANK(C2),"",LOOKUP(C2,'Objets de gestion'!C:C,'Objets de gestion'!E:E)) &IF(ISBLANK(D2),""," "&LOOKUP(D2,Articles!A:A,Articles!B:B)) &IF(ISBLANK(E2),""," "&LOOKUP(E2,'Objets de gestion'!C:C,'Objets de gestion'!E:E)) &IF(ISBLANK(F2),""," "&LOOKUP(F2,Articles!A:A,Articles!B:B)) &IF(ISBLANK(G2),""," "&LOOKUP(G2,'Objets de gestion'!C:C,'Objets de gestion'!E:E)) &IF(ISBLANK(H2),""," "&LOOKUP(H2,Articles!A:A,Articles!B:B)) &IF(ISBLANK(I2),""," "&LOOKUP(I2,'Objets de gestion'!C:C,'Objets de gestion'!E:E)) &IF(ISBLANK(J2),""," "&LOOKUP(J2,Articles!A:A,Articles!B:B)) &IF(ISBLANK(K2),""," "&LOOKUP(K2,'Objets de gestion'!C:C,'Objets de gestion'!E:E)) )) | Q2: =IF(AND(ISBLANK(A2),ISBLANK(B2),ISBLANK(C2),ISBLANK(E2),ISBLANK(L2)),"",IF(OR(ISBLANK(A2),ISBLANK(B2),ISBLANK(C2),ISBLANK(E2),ISBLANK(L2)),"-", LOOKUP(B2,'Type de champ'!B:B,'Type de champ'!C:C))) | R2: =IF(AND(ISBLANK(A2),ISBLANK(B2),ISBLANK(E2),ISBLANK(G2),ISBLANK(L2)),"",IF(OR(ISBLANK(A2),ISBLANK(B2),ISBLANK(E2),ISBLANK(G2),ISBLANK(L2)),"-", A2))
M3: =IF(AND(ISBLANK(A3),ISBLANK(B3),ISBLANK(E3),ISBLANK(G3),ISBLANK(L3)),"",IF(OR(ISBLANK(A3),ISBLANK(B3),ISBLANK(E3),ISBLANK(G3),ISBLANK(L3)),"-",LEN(Tableau47[[#This Row],[Code]]))) | N3: =IF(AND(ISBLANK(A3),ISBLANK(B3),ISBLANK(C3),ISBLANK(E3),ISBLANK(L3)),"",IF(OR(ISBLANK(A3),ISBLANK(B3),ISBLANK(C3),ISBLANK(E3),ISBLANK(L3)),"à compléter", IF(L3="Normal", LOOKUP(B3,'Type de champ'!B:B,'Type de champ'!A:A) &IF(COUNTIF('Objets de gestion'!C:C,K3)=0,"","_"&LOOKUP(K3,'Objets de gestion'!C:C,'Objets de gestion'!F:F)) &IF(COUNTIF('Objets de gestion'!C:C,I3)=0,"","_"&LOOKUP(I3,'Objets de gestion'!C:C,'Objets de gestion'!F:F)) &IF(COUNTIF('Objets de gestion'!C:C,G3)=0,"","_"&LOOKUP(G3,'Objets de gestion'!C:C,'Objets de gestion'!F:F)) &IF(COUNTIF('Objets de gestion'!C:C,E3)=0,"","_"&LOOKUP(E3,'Objets de gestion'!C:C,'Objets de gestion'!F:F)) &IF(OR(C3="booléen",COUNTIF('Objets de gestion'!C:C,C3)=0),"","_"&LOOKUP(C3,'Objets de gestion'!C:C,'Objets de gestion'!F:F)), IF(L3="Forcé", LOOKUP(B3,'Type de champ'!B:B,'Type de champ'!A:A) &IF(COUNTIF('Objets de gestion'!C:C,E3)=0,"","_"&LOOKUP(E3,'Objets de gestion'!C:C,'Objets de gestion'!F:F)) &IF(COUNTIF('Objets de gestion'!C:C,G3)=0,"","_"&LOOKUP(G3,'Objets de gestion'!C:C,'Objets de gestion'!F:F)) &IF(COUNTIF('Objets de gestion'!C:C,I3)=0,"","_"&LOOKUP(I3,'Objets de gestion'!C:C,'Objets de gestion'!F:F)) &IF(COUNTIF('Objets de gestion'!C:C,K3)=0,"","_"&LOOKUP(K3,'Objets de gestion'!C:C,'Objets de gestion'!F:F)) &IF(OR(C3="booléen",COUNTIF('Objets de gestion'!C:C,C3)=0),"","_"&LOOKUP(C3,'Objets de gestion'!C:C,'Objets de gestion'!F:F)) )))) | O3: =IF(AND(ISBLANK(A3),ISBLANK(B3),ISBLANK(C3),ISBLANK(E3),ISBLANK(L3)),"",IF(OR(ISBLANK(A3),ISBLANK(B3),ISBLANK(C3),ISBLANK(E3),ISBLANK(L3)),"-", C3&" "&IF(ISBLANK(E3),"",D3&" "&E3&" ")&IF(ISBLANK(G3),"",F3&" "&G3&" ")&IF(ISBLANK(I3),"",H3&" "&I3&" ")&IF(ISBLANK(K3),"",J3&" "&K3&" "))) | P3: =IF(AND(ISBLANK(A3),ISBLANK(B3),ISBLANK(C3),ISBLANK(E3),ISBLANK(L3)),"",IF(OR(ISBLANK(A3),ISBLANK(B3),ISBLANK(C3),ISBLANK(E3),ISBLANK(L3)),"-", IF(ISBLANK(C3),"",LOOKUP(C3,'Objets de gestion'!C:C,'Objets de gestion'!E:E)) &IF(ISBLANK(D3),""," "&LOOKUP(D3,Articles!A:A,Articles!B:B)) &IF(ISBLANK(E3),""," "&LOOKUP(E3,'Objets de gestion'!C:C,'Objets de gestion'!E:E)) &IF(ISBLANK(F3),""," "&LOOKUP(F3,Articles!A:A,Articles!B:B)) &IF(ISBLANK(G3),""," "&LOOKUP(G3,'Objets de gestion'!C:C,'Objets de gestion'!E:E)) &IF(ISBLANK(H3),""," "&LOOKUP(H3,Articles!A:A,Articles!B:B)) &IF(ISBLANK(I3),""," "&LOOKUP(I3,'Objets de gestion'!C:C,'Objets de gestion'!E:E)) &IF(ISBLANK(J3),""," "&LOOKUP(J3,Articles!A:A,Articles!B:B)) &IF(ISBLANK(K3),""," "&LOOKUP(K3,'Objets de gestion'!C:C,'Objets de gestion'!E:E)) )) | Q3: =IF(AND(ISBLANK(A3),ISBLANK(B3),ISBLANK(C3),ISBLANK(E3),ISBLANK(L3)),"",IF(OR(ISBLANK(A3),ISBLANK(B3),ISBLANK(C3),ISBLANK(E3),ISBLANK(L3)),"-", LOOKUP(B3,'Type de champ'!B:B,'Type de champ'!C:C))) | R3: =IF(AND(ISBLANK(A3),ISBLANK(B3),ISBLANK(E3),ISBLANK(G3),ISBLANK(L3)),"",IF(OR(ISBLANK(A3),ISBLANK(B3),ISBLANK(E3),ISBLANK(G3),ISBLANK(L3)),"-", A3))
M4: =IF(AND(ISBLANK(A4),ISBLANK(B4),ISBLANK(E4),ISBLANK(G4),ISBLANK(L4)),"",IF(OR(ISBLANK(A4),ISBLANK(B4),ISBLANK(E4),ISBLANK(G4),ISBLANK(L4)),"-",LEN(Tableau47[[#This Row],[Code]]))) | N4: =IF(AND(ISBLANK(A4),ISBLANK(B4),ISBLANK(C4),ISBLANK(E4),ISBLANK(L4)),"",IF(OR(ISBLANK(A4),ISBLANK(B4),ISBLANK(C4),ISBLANK(E4),ISBLANK(L4)),"à compléter", IF(L4="Normal", LOOKUP(B4,'Type de champ'!B:B,'Type de champ'!A:A) &IF(COUNTIF('Objets de gestion'!C:C,K4)=0,"","_"&LOOKUP(K4,'Objets de gestion'!C:C,'Objets de gestion'!F:F)) &IF(COUNTIF('Objets de gestion'!C:C,I4)=0,"","_"&LOOKUP(I4,'Objets de gestion'!C:C,'Objets de gestion'!F:F)) &IF(COUNTIF('Objets de gestion'!C:C,G4)=0,"","_"&LOOKUP(G4,'Objets de gestion'!C:C,'Objets de gestion'!F:F)) &IF(COUNTIF('Objets de gestion'!C:C,E4)=0,"","_"&LOOKUP(E4,'Objets de gestion'!C:C,'Objets de gestion'!F:F)) &IF(OR(C4="booléen",COUNTIF('Objets de gestion'!C:C,C4)=0),"","_"&LOOKUP(C4,'Objets de gestion'!C:C,'Objets de gestion'!F:F)), IF(L4="Forcé", LOOKUP(B4,'Type de champ'!B:B,'Type de champ'!A:A) &IF(COUNTIF('Objets de gestion'!C:C,E4)=0,"","_"&LOOKUP(E4,'Objets de gestion'!C:C,'Objets de gestion'!F:F)) &IF(COUNTIF('Objets de gestion'!C:C,G4)=0,"","_"&LOOKUP(G4,'Objets de gestion'!C:C,'Objets de gestion'!F:F)) &IF(COUNTIF('Objets de gestion'!C:C,I4)=0,"","_"&LOOKUP(I4,'Objets de gestion'!C:C,'Objets de gestion'!F:F)) &IF(COUNTIF('Objets de gestion'!C:C,K4)=0,"","_"&LOOKUP(K4,'Objets de gestion'!C:C,'Objets de gestion'!F:F)) &IF(OR(C4="booléen",COUNTIF('Objets de gestion'!C:C,C4)=0),"","_"&LOOKUP(C4,'Objets de gestion'!C:C,'Objets de gestion'!F:F)) )))) | O4: =IF(AND(ISBLANK(A4),ISBLANK(B4),ISBLANK(C4),ISBLANK(E4),ISBLANK(L4)),"",IF(OR(ISBLANK(A4),ISBLANK(B4),ISBLANK(C4),ISBLANK(E4),ISBLANK(L4)),"-", C4&" "&IF(ISBLANK(E4),"",D4&" "&E4&" ")&IF(ISBLANK(G4),"",F4&" "&G4&" ")&IF(ISBLANK(I4),"",H4&" "&I4&" ")&IF(ISBLANK(K4),"",J4&" "&K4&" "))) | P4: =IF(AND(ISBLANK(A4),ISBLANK(B4),ISBLANK(C4),ISBLANK(E4),ISBLANK(L4)),"",IF(OR(ISBLANK(A4),ISBLANK(B4),ISBLANK(C4),ISBLANK(E4),ISBLANK(L4)),"-", IF(ISBLANK(C4),"",LOOKUP(C4,'Objets de gestion'!C:C,'Objets de gestion'!E:E)) &IF(ISBLANK(D4),""," "&LOOKUP(D4,Articles!A:A,Articles!B:B)) &IF(ISBLANK(E4),""," "&LOOKUP(E4,'Objets de gestion'!C:C,'Objets de gestion'!E:E)) &IF(ISBLANK(F4),""," "&LOOKUP(F4,Articles!A:A,Articles!B:B)) &IF(ISBLANK(G4),""," "&LOOKUP(G4,'Objets de gestion'!C:C,'Objets de gestion'!E:E)) &IF(ISBLANK(H4),""," "&LOOKUP(H4,Articles!A:A,Articles!B:B)) &IF(ISBLANK(I4),""," "&LOOKUP(I4,'Objets de gestion'!C:C,'Objets de gestion'!E:E)) &IF(ISBLANK(J4),""," "&LOOKUP(J4,Articles!A:A,Articles!B:B)) &IF(ISBLANK(K4),""," "&LOOKUP(K4,'Objets de gestion'!C:C,'Objets de gestion'!E:E)) )) | Q4: =IF(AND(ISBLANK(A4),ISBLANK(B4),ISBLANK(C4),ISBLANK(E4),ISBLANK(L4)),"",IF(OR(ISBLANK(A4),ISBLANK(B4),ISBLANK(C4),ISBLANK(E4),ISBLANK(L4)),"-", LOOKUP(B4,'Type de champ'!B:B,'Type de champ'!C:C))) | R4: =IF(AND(ISBLANK(A4),ISBLANK(B4),ISBLANK(E4),ISBLANK(G4),ISBLANK(L4)),"",IF(OR(ISBLANK(A4),ISBLANK(B4),ISBLANK(E4),ISBLANK(G4),ISBLANK(L4)),"-", A4))
M5: =IF(AND(ISBLANK(A5),ISBLANK(B5),ISBLANK(E5),ISBLANK(G5),ISBLANK(L5)),"",IF(OR(ISBLANK(A5),ISBLANK(B5),ISBLANK(E5),ISBLANK(G5),ISBLANK(L5)),"-",LEN(Tableau47[[#This Row],[Code]]))) | N5: =IF(AND(ISBLANK(A5),ISBLANK(B5),ISBLANK(C5),ISBLANK(E5),ISBLANK(L5)),"",IF(OR(ISBLANK(A5),ISBLANK(B5),ISBLANK(C5),ISBLANK(E5),ISBLANK(L5)),"à compléter", IF(L5="Normal", LOOKUP(B5,'Type de champ'!B:B,'Type de champ'!A:A) &IF(COUNTIF('Objets de gestion'!C:C,K5)=0,"","_"&LOOKUP(K5,'Objets de gestion'!C:C,'Objets de gestion'!F:F)) &IF(COUNTIF('Objets de gestion'!C:C,I5)=0,"","_"&LOOKUP(I5,'Objets de gestion'!C:C,'Objets de gestion'!F:F)) &IF(COUNTIF('Objets de gestion'!C:C,G5)=0,"","_"&LOOKUP(G5,'Objets de gestion'!C:C,'Objets de gestion'!F:F)) &IF(COUNTIF('Objets de gestion'!C:C,E5)=0,"","_"&LOOKUP(E5,'Objets de gestion'!C:C,'Objets de gestion'!F:F)) &IF(OR(C5="booléen",COUNTIF('Objets de gestion'!C:C,C5)=0),"","_"&LOOKUP(C5,'Objets de gestion'!C:C,'Objets de gestion'!F:F)), IF(L5="Forcé", LOOKUP(B5,'Type de champ'!B:B,'Type de champ'!A:A) &IF(COUNTIF('Objets de gestion'!C:C,E5)=0,"","_"&LOOKUP(E5,'Objets de gestion'!C:C,'Objets de gestion'!F:F)) &IF(COUNTIF('Objets de gestion'!C:C,G5)=0,"","_"&LOOKUP(G5,'Objets de gestion'!C:C,'Objets de gestion'!F:F)) &IF(COUNTIF('Objets de gestion'!C:C,I5)=0,"","_"&LOOKUP(I5,'Objets de gestion'!C:C,'Objets de gestion'!F:F)) &IF(COUNTIF('Objets de gestion'!C:C,K5)=0,"","_"&LOOKUP(K5,'Objets de gestion'!C:C,'Objets de gestion'!F:F)) &IF(OR(C5="booléen",COUNTIF('Objets de gestion'!C:C,C5)=0),"","_"&LOOKUP(C5,'Objets de gestion'!C:C,'Objets de gestion'!F:F)) )))) | O5: =IF(AND(ISBLANK(A5),ISBLANK(B5),ISBLANK(C5),ISBLANK(E5),ISBLANK(L5)),"",IF(OR(ISBLANK(A5),ISBLANK(B5),ISBLANK(C5),ISBLANK(E5),ISBLANK(L5)),"-", C5&" "&IF(ISBLANK(E5),"",D5&" "&E5&" ")&IF(ISBLANK(G5),"",F5&" "&G5&" ")&IF(ISBLANK(I5),"",H5&" "&I5&" ")&IF(ISBLANK(K5),"",J5&" "&K5&" "))) | P5: =IF(AND(ISBLANK(A5),ISBLANK(B5),ISBLANK(C5),ISBLANK(E5),ISBLANK(L5)),"",IF(OR(ISBLANK(A5),ISBLANK(B5),ISBLANK(C5),ISBLANK(E5),ISBLANK(L5)),"-", IF(ISBLANK(C5),"",LOOKUP(C5,'Objets de gestion'!C:C,'Objets de gestion'!E:E)) &IF(ISBLANK(D5),""," "&LOOKUP(D5,Articles!A:A,Articles!B:B)) &IF(ISBLANK(E5),""," "&LOOKUP(E5,'Objets de gestion'!C:C,'Objets de gestion'!E:E)) &IF(ISBLANK(F5),""," "&LOOKUP(F5,Articles!A:A,Articles!B:B)) &IF(ISBLANK(G5),""," "&LOOKUP(G5,'Objets de gestion'!C:C,'Objets de gestion'!E:E)) &IF(ISBLANK(H5),""," "&LOOKUP(H5,Articles!A:A,Articles!B:B)) &IF(ISBLANK(I5),""," "&LOOKUP(I5,'Objets de gestion'!C:C,'Objets de gestion'!E:E)) &IF(ISBLANK(J5),""," "&LOOKUP(J5,Articles!A:A,Articles!B:B)) &IF(ISBLANK(K5),""," "&LOOKUP(K5,'Objets de gestion'!C:C,'Objets de gestion'!E:E)) )) | Q5: =IF(AND(ISBLANK(A5),ISBLANK(B5),ISBLANK(C5),ISBLANK(E5),ISBLANK(L5)),"",IF(OR(ISBLANK(A5),ISBLANK(B5),ISBLANK(C5),ISBLANK(E5),ISBLANK(L5)),"-", LOOKUP(B5,'Type de champ'!B:B,'Type de champ'!C:C))) | R5: =IF(AND(ISBLANK(A5),ISBLANK(B5),ISBLANK(E5),ISBLANK(G5),ISBLANK(L5)),"",IF(OR(ISBLANK(A5),ISBLANK(B5),ISBLANK(E5),ISBLANK(G5),ISBLANK(L5)),"-", A5))
M6: =IF(AND(ISBLANK(A6),ISBLANK(B6),ISBLANK(E6),ISBLANK(G6),ISBLANK(L6)),"",IF(OR(ISBLANK(A6),ISBLANK(B6),ISBLANK(E6),ISBLANK(G6),ISBLANK(L6)),"-",LEN(Tableau47[[#This Row],[Code]]))) | N6: =IF(AND(ISBLANK(A6),ISBLANK(B6),ISBLANK(C6),ISBLANK(E6),ISBLANK(L6)),"",IF(OR(ISBLANK(A6),ISBLANK(B6),ISBLANK(C6),ISBLANK(E6),ISBLANK(L6)),"à compléter", IF(L6="Normal", LOOKUP(B6,'Type de champ'!B:B,'Type de champ'!A:A) &IF(COUNTIF('Objets de gestion'!C:C,K6)=0,"","_"&LOOKUP(K6,'Objets de gestion'!C:C,'Objets de gestion'!F:F)) &IF(COUNTIF('Objets de gestion'!C:C,I6)=0,"","_"&LOOKUP(I6,'Objets de gestion'!C:C,'Objets de gestion'!F:F)) &IF(COUNTIF('Objets de gestion'!C:C,G6)=0,"","_"&LOOKUP(G6,'Objets de gestion'!C:C,'Objets de gestion'!F:F)) &IF(COUNTIF('Objets de gestion'!C:C,E6)=0,"","_"&LOOKUP(E6,'Objets de gestion'!C:C,'Objets de gestion'!F:F)) &IF(OR(C6="booléen",COUNTIF('Objets de gestion'!C:C,C6)=0),"","_"&LOOKUP(C6,'Objets de gestion'!C:C,'Objets de gestion'!F:F)), IF(L6="Forcé", LOOKUP(B6,'Type de champ'!B:B,'Type de champ'!A:A) &IF(COUNTIF('Objets de gestion'!C:C,E6)=0,"","_"&LOOKUP(E6,'Objets de gestion'!C:C,'Objets de gestion'!F:F)) &IF(COUNTIF('Objets de gestion'!C:C,G6)=0,"","_"&LOOKUP(G6,'Objets de gestion'!C:C,'Objets de gestion'!F:F)) &IF(COUNTIF('Objets de gestion'!C:C,I6)=0,"","_"&LOOKUP(I6,'Objets de gestion'!C:C,'Objets de gestion'!F:F)) &IF(COUNTIF('Objets de gestion'!C:C,K6)=0,"","_"&LOOKUP(K6,'Objets de gestion'!C:C,'Objets de gestion'!F:F)) &IF(OR(C6="booléen",COUNTIF('Objets de gestion'!C:C,C6)=0),"","_"&LOOKUP(C6,'Objets de gestion'!C:C,'Objets de gestion'!F:F)) )))) | O6: =IF(AND(ISBLANK(A6),ISBLANK(B6),ISBLANK(C6),ISBLANK(E6),ISBLANK(L6)),"",IF(OR(ISBLANK(A6),ISBLANK(B6),ISBLANK(C6),ISBLANK(E6),ISBLANK(L6)),"-", C6&" "&IF(ISBLANK(E6),"",D6&" "&E6&" ")&IF(ISBLANK(G6),"",F6&" "&G6&" ")&IF(ISBLANK(I6),"",H6&" "&I6&" ")&IF(ISBLANK(K6),"",J6&" "&K6&" "))) | P6: =IF(AND(ISBLANK(A6),ISBLANK(B6),ISBLANK(C6),ISBLANK(E6),ISBLANK(L6)),"",IF(OR(ISBLANK(A6),ISBLANK(B6),ISBLANK(C6),ISBLANK(E6),ISBLANK(L6)),"-", IF(ISBLANK(C6),"",LOOKUP(C6,'Objets de gestion'!C:C,'Objets de gestion'!E:E)) &IF(ISBLANK(D6),""," "&LOOKUP(D6,Articles!A:A,Articles!B:B)) &IF(ISBLANK(E6),""," "&LOOKUP(E6,'Objets de gestion'!C:C,'Objets de gestion'!E:E)) &IF(ISBLANK(F6),""," "&LOOKUP(F6,Articles!A:A,Articles!B:B)) &IF(ISBLANK(G6),""," "&LOOKUP(G6,'Objets de gestion'!C:C,'Objets de gestion'!E:E)) &IF(ISBLANK(H6),""," "&LOOKUP(H6,Articles!A:A,Articles!B:B)) &IF(ISBLANK(I6),""," "&LOOKUP(I6,'Objets de gestion'!C:C,'Objets de gestion'!E:E)) &IF(ISBLANK(J6),""," "&LOOKUP(J6,Articles!A:A,Articles!B:B)) &IF(ISBLANK(K6),""," "&LOOKUP(K6,'Objets de gestion'!C:C,'Objets de gestion'!E:E)) )) | Q6: =IF(AND(ISBLANK(A6),ISBLANK(B6),ISBLANK(C6),ISBLANK(E6),ISBLANK(L6)),"",IF(OR(ISBLANK(A6),ISBLANK(B6),ISBLANK(C6),ISBLANK(E6),ISBLANK(L6)),"-", LOOKUP(B6,'Type de champ'!B:B,'Type de champ'!C:C))) | R6: =IF(AND(ISBLANK(A6),ISBLANK(B6),ISBLANK(E6),ISBLANK(G6),ISBLANK(L6)),"",IF(OR(ISBLANK(A6),ISBLANK(B6),ISBLANK(E6),ISBLANK(G6),ISBLANK(L6)),"-", A6))
M7: =IF(AND(ISBLANK(A7),ISBLANK(B7),ISBLANK(E7),ISBLANK(G7),ISBLANK(L7)),"",IF(OR(ISBLANK(A7),ISBLANK(B7),ISBLANK(E7),ISBLANK(G7),ISBLANK(L7)),"-",LEN(Tableau47[[#This Row],[Code]]))) | N7: =IF(AND(ISBLANK(A7),ISBLANK(B7),ISBLANK(C7),ISBLANK(E7),ISBLANK(L7)),"",IF(OR(ISBLANK(A7),ISBLANK(B7),ISBLANK(C7),ISBLANK(E7),ISBLANK(L7)),"à compléter", IF(L7="Normal", LOOKUP(B7,'Type de champ'!B:B,'Type de champ'!A:A) &IF(COUNTIF('Objets de gestion'!C:C,K7)=0,"","_"&LOOKUP(K7,'Objets de gestion'!C:C,'Objets de gestion'!F:F)) &IF(COUNTIF('Objets de gestion'!C:C,I7)=0,"","_"&LOOKUP(I7,'Objets de gestion'!C:C,'Objets de gestion'!F:F)) &IF(COUNTIF('Objets de gestion'!C:C,G7)=0,"","_"&LOOKUP(G7,'Objets de gestion'!C:C,'Objets de gestion'!F:F)) &IF(COUNTIF('Objets de gestion'!C:C,E7)=0,"","_"&LOOKUP(E7,'Objets de gestion'!C:C,'Objets de gestion'!F:F)) &IF(OR(C7="booléen",COUNTIF('Objets de gestion'!C:C,C7)=0),"","_"&LOOKUP(C7,'Objets de gestion'!C:C,'Objets de gestion'!F:F)), IF(L7="Forcé", LOOKUP(B7,'Type de champ'!B:B,'Type de champ'!A:A) &IF(COUNTIF('Objets de gestion'!C:C,E7)=0,"","_"&LOOKUP(E7,'Objets de gestion'!C:C,'Objets de gestion'!F:F)) &IF(COUNTIF('Objets de gestion'!C:C,G7)=0,"","_"&LOOKUP(G7,'Objets de gestion'!C:C,'Objets de gestion'!F:F)) &IF(COUNTIF('Objets de gestion'!C:C,I7)=0,"","_"&LOOKUP(I7,'Objets de gestion'!C:C,'Objets de gestion'!F:F)) &IF(COUNTIF('Objets de gestion'!C:C,K7)=0,"","_"&LOOKUP(K7,'Objets de gestion'!C:C,'Objets de gestion'!F:F)) &IF(OR(C7="booléen",COUNTIF('Objets de gestion'!C:C,C7)=0),"","_"&LOOKUP(C7,'Objets de gestion'!C:C,'Objets de gestion'!F:F)) )))) | O7: =IF(AND(ISBLANK(A7),ISBLANK(B7),ISBLANK(C7),ISBLANK(E7),ISBLANK(L7)),"",IF(OR(ISBLANK(A7),ISBLANK(B7),ISBLANK(C7),ISBLANK(E7),ISBLANK(L7)),"-", C7&" "&IF(ISBLANK(E7),"",D7&" "&E7&" ")&IF(ISBLANK(G7),"",F7&" "&G7&" ")&IF(ISBLANK(I7),"",H7&" "&I7&" ")&IF(ISBLANK(K7),"",J7&" "&K7&" "))) | P7: =IF(AND(ISBLANK(A7),ISBLANK(B7),ISBLANK(C7),ISBLANK(E7),ISBLANK(L7)),"",IF(OR(ISBLANK(A7),ISBLANK(B7),ISBLANK(C7),ISBLANK(E7),ISBLANK(L7)),"-", IF(ISBLANK(C7),"",LOOKUP(C7,'Objets de gestion'!C:C,'Objets de gestion'!E:E)) &IF(ISBLANK(D7),""," "&LOOKUP(D7,Articles!A:A,Articles!B:B)) &IF(ISBLANK(E7),""," "&LOOKUP(E7,'Objets de gestion'!C:C,'Objets de gestion'!E:E)) &IF(ISBLANK(F7),""," "&LOOKUP(F7,Articles!A:A,Articles!B:B)) &IF(ISBLANK(G7),""," "&LOOKUP(G7,'Objets de gestion'!C:C,'Objets de gestion'!E:E)) &IF(ISBLANK(H7),""," "&LOOKUP(H7,Articles!A:A,Articles!B:B)) &IF(ISBLANK(I7),""," "&LOOKUP(I7,'Objets de gestion'!C:C,'Objets de gestion'!E:E)) &IF(ISBLANK(J7),""," "&LOOKUP(J7,Articles!A:A,Articles!B:B)) &IF(ISBLANK(K7),""," "&LOOKUP(K7,'Objets de gestion'!C:C,'Objets de gestion'!E:E)) )) | Q7: =IF(AND(ISBLANK(A7),ISBLANK(B7),ISBLANK(C7),ISBLANK(E7),ISBLANK(L7)),"",IF(OR(ISBLANK(A7),ISBLANK(B7),ISBLANK(C7),ISBLANK(E7),ISBLANK(L7)),"-", LOOKUP(B7,'Type de champ'!B:B,'Type de champ'!C:C))) | R7: =IF(AND(ISBLANK(A7),ISBLANK(B7),ISBLANK(E7),ISBLANK(G7),ISBLANK(L7)),"",IF(OR(ISBLANK(A7),ISBLANK(B7),ISBLANK(E7),ISBLANK(G7),ISBLANK(L7)),"-", A7))
M8: =IF(AND(ISBLANK(A8),ISBLANK(B8),ISBLANK(E8),ISBLANK(G8),ISBLANK(L8)),"",IF(OR(ISBLANK(A8),ISBLANK(B8),ISBLANK(E8),ISBLANK(G8),ISBLANK(L8)),"-",LEN(Tableau47[[#This Row],[Code]]))) | N8: =IF(AND(ISBLANK(A8),ISBLANK(B8),ISBLANK(C8),ISBLANK(E8),ISBLANK(L8)),"",IF(OR(ISBLANK(A8),ISBLANK(B8),ISBLANK(C8),ISBLANK(E8),ISBLANK(L8)),"à compléter", IF(L8="Normal", LOOKUP(B8,'Type de champ'!B:B,'Type de champ'!A:A) &IF(COUNTIF('Objets de gestion'!C:C,K8)=0,"","_"&LOOKUP(K8,'Objets de gestion'!C:C,'Objets de gestion'!F:F)) &IF(COUNTIF('Objets de gestion'!C:C,I8)=0,"","_"&LOOKUP(I8,'Objets de gestion'!C:C,'Objets de gestion'!F:F)) &IF(COUNTIF('Objets de gestion'!C:C,G8)=0,"","_"&LOOKUP(G8,'Objets de gestion'!C:C,'Objets de gestion'!F:F)) &IF(COUNTIF('Objets de gestion'!C:C,E8)=0,"","_"&LOOKUP(E8,'Objets de gestion'!C:C,'Objets de gestion'!F:F)) &IF(OR(C8="booléen",COUNTIF('Objets de gestion'!C:C,C8)=0),"","_"&LOOKUP(C8,'Objets de gestion'!C:C,'Objets de gestion'!F:F)), IF(L8="Forcé", LOOKUP(B8,'Type de champ'!B:B,'Type de champ'!A:A) &IF(COUNTIF('Objets de gestion'!C:C,E8)=0,"","_"&LOOKUP(E8,'Objets de gestion'!C:C,'Objets de gestion'!F:F)) &IF(COUNTIF('Objets de gestion'!C:C,G8)=0,"","_"&LOOKUP(G8,'Objets de gestion'!C:C,'Objets de gestion'!F:F)) &IF(COUNTIF('Objets de gestion'!C:C,I8)=0,"","_"&LOOKUP(I8,'Objets de gestion'!C:C,'Objets de gestion'!F:F)) &IF(COUNTIF('Objets de gestion'!C:C,K8)=0,"","_"&LOOKUP(K8,'Objets de gestion'!C:C,'Objets de gestion'!F:F)) &IF(OR(C8="booléen",COUNTIF('Objets de gestion'!C:C,C8)=0),"","_"&LOOKUP(C8,'Objets de gestion'!C:C,'Objets de gestion'!F:F)) )))) | O8: =IF(AND(ISBLANK(A8),ISBLANK(B8),ISBLANK(C8),ISBLANK(E8),ISBLANK(L8)),"",IF(OR(ISBLANK(A8),ISBLANK(B8),ISBLANK(C8),ISBLANK(E8),ISBLANK(L8)),"-", C8&" "&IF(ISBLANK(E8),"",D8&" "&E8&" ")&IF(ISBLANK(G8),"",F8&" "&G8&" ")&IF(ISBLANK(I8),"",H8&" "&I8&" ")&IF(ISBLANK(K8),"",J8&" "&K8&" "))) | P8: =IF(AND(ISBLANK(A8),ISBLANK(B8),ISBLANK(C8),ISBLANK(E8),ISBLANK(L8)),"",IF(OR(ISBLANK(A8),ISBLANK(B8),ISBLANK(C8),ISBLANK(E8),ISBLANK(L8)),"-", IF(ISBLANK(C8),"",LOOKUP(C8,'Objets de gestion'!C:C,'Objets de gestion'!E:E)) &IF(ISBLANK(D8),""," "&LOOKUP(D8,Articles!A:A,Articles!B:B)) &IF(ISBLANK(E8),""," "&LOOKUP(E8,'Objets de gestion'!C:C,'Objets de gestion'!E:E)) &IF(ISBLANK(F8),""," "&LOOKUP(F8,Articles!A:A,Articles!B:B)) &IF(ISBLANK(G8),""," "&LOOKUP(G8,'Objets de gestion'!C:C,'Objets de gestion'!E:E)) &IF(ISBLANK(H8),""," "&LOOKUP(H8,Articles!A:A,Articles!B:B)) &IF(ISBLANK(I8),""," "&LOOKUP(I8,'Objets de gestion'!C:C,'Objets de gestion'!E:E)) &IF(ISBLANK(J8),""," "&LOOKUP(J8,Articles!A:A,Articles!B:B)) &IF(ISBLANK(K8),""," "&LOOKUP(K8,'Objets de gestion'!C:C,'Objets de gestion'!E:E)) )) | Q8: =IF(AND(ISBLANK(A8),ISBLANK(B8),ISBLANK(C8),ISBLANK(E8),ISBLANK(L8)),"",IF(OR(ISBLANK(A8),ISBLANK(B8),ISBLANK(C8),ISBLANK(E8),ISBLANK(L8)),"-", LOOKUP(B8,'Type de champ'!B:B,'Type de champ'!C:C))) | R8: =IF(AND(ISBLANK(A8),ISBLANK(B8),ISBLANK(E8),ISBLANK(G8),ISBLANK(L8)),"",IF(OR(ISBLANK(A8),ISBLANK(B8),ISBLANK(E8),ISBLANK(G8),ISBLANK(L8)),"-", A8))
M9: =IF(AND(ISBLANK(A9),ISBLANK(B9),ISBLANK(E9),ISBLANK(G9),ISBLANK(L9)),"",IF(OR(ISBLANK(A9),ISBLANK(B9),ISBLANK(E9),ISBLANK(G9),ISBLANK(L9)),"-",LEN(Tableau47[[#This Row],[Code]]))) | N9: =IF(AND(ISBLANK(A9),ISBLANK(B9),ISBLANK(C9),ISBLANK(E9),ISBLANK(L9)),"",IF(OR(ISBLANK(A9),ISBLANK(B9),ISBLANK(C9),ISBLANK(E9),ISBLANK(L9)),"à compléter", IF(L9="Normal", LOOKUP(B9,'Type de champ'!B:B,'Type de champ'!A:A) &IF(COUNTIF('Objets de gestion'!C:C,K9)=0,"","_"&LOOKUP(K9,'Objets de gestion'!C:C,'Objets de gestion'!F:F)) &IF(COUNTIF('Objets de gestion'!C:C,I9)=0,"","_"&LOOKUP(I9,'Objets de gestion'!C:C,'Objets de gestion'!F:F)) &IF(COUNTIF('Objets de gestion'!C:C,G9)=0,"","_"&LOOKUP(G9,'Objets de gestion'!C:C,'Objets de gestion'!F:F)) &IF(COUNTIF('Objets de gestion'!C:C,E9)=0,"","_"&LOOKUP(E9,'Objets de gestion'!C:C,'Objets de gestion'!F:F)) &IF(OR(C9="booléen",COUNTIF('Objets de gestion'!C:C,C9)=0),"","_"&LOOKUP(C9,'Objets de gestion'!C:C,'Objets de gestion'!F:F)), IF(L9="Forcé", LOOKUP(B9,'Type de champ'!B:B,'Type de champ'!A:A) &IF(COUNTIF('Objets de gestion'!C:C,E9)=0,"","_"&LOOKUP(E9,'Objets de gestion'!C:C,'Objets de gestion'!F:F)) &IF(COUNTIF('Objets de gestion'!C:C,G9)=0,"","_"&LOOKUP(G9,'Objets de gestion'!C:C,'Objets de gestion'!F:F)) &IF(COUNTIF('Objets de gestion'!C:C,I9)=0,"","_"&LOOKUP(I9,'Objets de gestion'!C:C,'Objets de gestion'!F:F)) &IF(COUNTIF('Objets de gestion'!C:C,K9)=0,"","_"&LOOKUP(K9,'Objets de gestion'!C:C,'Objets de gestion'!F:F)) &IF(OR(C9="booléen",COUNTIF('Objets de gestion'!C:C,C9)=0),"","_"&LOOKUP(C9,'Objets de gestion'!C:C,'Objets de gestion'!F:F)) )))) | O9: =IF(AND(ISBLANK(A9),ISBLANK(B9),ISBLANK(C9),ISBLANK(E9),ISBLANK(L9)),"",IF(OR(ISBLANK(A9),ISBLANK(B9),ISBLANK(C9),ISBLANK(E9),ISBLANK(L9)),"-", C9&" "&IF(ISBLANK(E9),"",D9&" "&E9&" ")&IF(ISBLANK(G9),"",F9&" "&G9&" ")&IF(ISBLANK(I9),"",H9&" "&I9&" ")&IF(ISBLANK(K9),"",J9&" "&K9&" "))) | P9: =IF(AND(ISBLANK(A9),ISBLANK(B9),ISBLANK(C9),ISBLANK(E9),ISBLANK(L9)),"",IF(OR(ISBLANK(A9),ISBLANK(B9),ISBLANK(C9),ISBLANK(E9),ISBLANK(L9)),"-", IF(ISBLANK(C9),"",LOOKUP(C9,'Objets de gestion'!C:C,'Objets de gestion'!E:E)) &IF(ISBLANK(D9),""," "&LOOKUP(D9,Articles!A:A,Articles!B:B)) &IF(ISBLANK(E9),""," "&LOOKUP(E9,'Objets de gestion'!C:C,'Objets de gestion'!E:E)) &IF(ISBLANK(F9),""," "&LOOKUP(F9,Articles!A:A,Articles!B:B)) &IF(ISBLANK(G9),""," "&LOOKUP(G9,'Objets de gestion'!C:C,'Objets de gestion'!E:E)) &IF(ISBLANK(H9),""," "&LOOKUP(H9,Articles!A:A,Articles!B:B)) &IF(ISBLANK(I9),""," "&LOOKUP(I9,'Objets de gestion'!C:C,'Objets de gestion'!E:E)) &IF(ISBLANK(J9),""," "&LOOKUP(J9,Articles!A:A,Articles!B:B)) &IF(ISBLANK(K9),""," "&LOOKUP(K9,'Objets de gestion'!C:C,'Objets de gestion'!E:E)) )) | Q9: =IF(AND(ISBLANK(A9),ISBLANK(B9),ISBLANK(C9),ISBLANK(E9),ISBLANK(L9)),"",IF(OR(ISBLANK(A9),ISBLANK(B9),ISBLANK(C9),ISBLANK(E9),ISBLANK(L9)),"-", LOOKUP(B9,'Type de champ'!B:B,'Type de champ'!C:C))) | R9: =IF(AND(ISBLANK(A9),ISBLANK(B9),ISBLANK(E9),ISBLANK(G9),ISBLANK(L9)),"",IF(OR(ISBLANK(A9),ISBLANK(B9),ISBLANK(E9),ISBLANK(G9),ISBLANK(L9)),"-", A9))
M10: =IF(AND(ISBLANK(A10),ISBLANK(B10),ISBLANK(E10),ISBLANK(G10),ISBLANK(L10)),"",IF(OR(ISBLANK(A10),ISBLANK(B10),ISBLANK(E10),ISBLANK(G10),ISBLANK(L10)),"-",LEN(Tableau47[[#This Row],[Code]]))) | N10: =IF(AND(ISBLANK(A10),ISBLANK(B10),ISBLANK(C10),ISBLANK(E10),ISBLANK(L10)),"",IF(OR(ISBLANK(A10),ISBLANK(B10),ISBLANK(C10),ISBLANK(E10),ISBLANK(L10)),"à compléter", IF(L10="Normal", LOOKUP(B10,'Type de champ'!B:B,'Type de champ'!A:A) &IF(COUNTIF('Objets de gestion'!C:C,K10)=0,"","_"&LOOKUP(K10,'Objets de gestion'!C:C,'Objets de gestion'!F:F)) &IF(COUNTIF('Objets de gestion'!C:C,I10)=0,"","_"&LOOKUP(I10,'Objets de gestion'!C:C,'Objets de gestion'!F:F)) &IF(COUNTIF('Objets de gestion'!C:C,G10)=0,"","_"&LOOKUP(G10,'Objets de gestion'!C:C,'Objets de gestion'!F:F)) &IF(COUNTIF('Objets de gestion'!C:C,E10)=0,"","_"&LOOKUP(E10,'Objets de gestion'!C:C,'Objets de gestion'!F:F)) &IF(OR(C10="booléen",COUNTIF('Objets de gestion'!C:C,C10)=0),"","_"&LOOKUP(C10,'Objets de gestion'!C:C,'Objets de gestion'!F:F)), IF(L10="Forcé", LOOKUP(B10,'Type de champ'!B:B,'Type de champ'!A:A) &IF(COUNTIF('Objets de gestion'!C:C,E10)=0,"","_"&LOOKUP(E10,'Objets de gestion'!C:C,'Objets de gestion'!F:F)) &IF(COUNTIF('Objets de gestion'!C:C,G10)=0,"","_"&LOOKUP(G10,'Objets de gestion'!C:C,'Objets de gestion'!F:F)) &IF(COUNTIF('Objets de gestion'!C:C,I10)=0,"","_"&LOOKUP(I10,'Objets de gestion'!C:C,'Objets de gestion'!F:F)) &IF(COUNTIF('Objets de gestion'!C:C,K10)=0,"","_"&LOOKUP(K10,'Objets de gestion'!C:C,'Objets de gestion'!F:F)) &IF(OR(C10="booléen",COUNTIF('Objets de gestion'!C:C,C10)=0),"","_"&LOOKUP(C10,'Objets de gestion'!C:C,'Objets de gestion'!F:F)) )))) | O10: =IF(AND(ISBLANK(A10),ISBLANK(B10),ISBLANK(C10),ISBLANK(E10),ISBLANK(L10)),"",IF(OR(ISBLANK(A10),ISBLANK(B10),ISBLANK(C10),ISBLANK(E10),ISBLANK(L10)),"-", C10&" "&IF(ISBLANK(E10),"",D10&" "&E10&" ")&IF(ISBLANK(G10),"",F10&" "&G10&" ")&IF(ISBLANK(I10),"",H10&" "&I10&" ")&IF(ISBLANK(K10),"",J10&" "&K10&" "))) | P10: =IF(AND(ISBLANK(A10),ISBLANK(B10),ISBLANK(C10),ISBLANK(E10),ISBLANK(L10)),"",IF(OR(ISBLANK(A10),ISBLANK(B10),ISBLANK(C10),ISBLANK(E10),ISBLANK(L10)),"-", IF(ISBLANK(C10),"",LOOKUP(C10,'Objets de gestion'!C:C,'Objets de gestion'!E:E)) &IF(ISBLANK(D10),""," "&LOOKUP(D10,Articles!A:A,Articles!B:B)) &IF(ISBLANK(E10),""," "&LOOKUP(E10,'Objets de gestion'!C:C,'Objets de gestion'!E:E)) &IF(ISBLANK(F10),""," "&LOOKUP(F10,Articles!A:A,Articles!B:B)) &IF(ISBLANK(G10),""," "&LOOKUP(G10,'Objets de gestion'!C:C,'Objets de gestion'!E:E)) &IF(ISBLANK(H10),""," "&LOOKUP(H10,Articles!A:A,Articles!B:B)) &IF(ISBLANK(I10),""," "&LOOKUP(I10,'Objets de gestion'!C:C,'Objets de gestion'!E:E)) &IF(ISBLANK(J10),""," "&LOOKUP(J10,Articles!A:A,Articles!B:B)) &IF(ISBLANK(K10),""," "&LOOKUP(K10,'Objets de gestion'!C:C,'Objets de gestion'!E:E)) )) | Q10: =IF(AND(ISBLANK(A10),ISBLANK(B10),ISBLANK(C10),ISBLANK(E10),ISBLANK(L10)),"",IF(OR(ISBLANK(A10),ISBLANK(B10),ISBLANK(C10),ISBLANK(E10),ISBLANK(L10)),"-", LOOKUP(B10,'Type de champ'!B:B,'Type de champ'!C:C))) | R10: =IF(AND(ISBLANK(A10),ISBLANK(B10),ISBLANK(E10),ISBLANK(G10),ISBLANK(L10)),"",IF(OR(ISBLANK(A10),ISBLANK(B10),ISBLANK(E10),ISBLANK(G10),ISBLANK(L10)),"-", A10))
