Workbook

Sheet A LIRE
A1: Document : | C1: Outil de nomenclature SIAD
A3: Interlocuteurs : | C3: Angéline JACQUINOT | D3: Carole ANDREOTTI
A5: Ce document permet de générer les codes des tables et champs d'une nomenclature ainsi que des libellés anglais. Il est là pour aider à compléter la demande de nomenclature.
A6: Il est décomposé en 4 parties : Tables, Champs, Objets de gestion/Articles et BIB/Type de table
A8: La feuille "Tables" permet de générer le code des tables (Domaine de valeurs et Datamart compris)
A9: À faire : | B9: Complèter les colonnes (par sélection dans la liste déroulante) : Nom du BIB, Type de table et Objet de gestion (jusquà 4 objets de gestion possible par table)
B10: ATTENTION : les colonnes après la barre vertical noire sont générés par du code Excel, merci de ne pas les toucher
A12: La feuille "Champs" permet de générer le code des champs (UID, code et libellé des domaines de valeurs compris).
A13: À faire : | B13: Complèter les colonnes (par sélection dans la liste déroulante) : Nom du BIB, Objet de gestion (+ article, objet de gestion, etc…) => jusquà 4 objets de gestion possible par champ
B14: ATTENTION : les colonnes après la barre vertical noire sont générés par du code Excel, merci de ne pas les toucher
A16: Les feuilles "Objets de gestion" et "Articles" sont des référentiels. Ils peuvent être agrémenter de nouvelles lignes mais en aucun cas être mofifiés.
A17: À faire : | B17: Si un Objet de gestion n'est pas présent : - insérer une nouvelle ligne dans le tableau (Ctrl + "+") ou placer vous à la fin du tableau - renseigner la date du jour, le nom français, une description si besoin, le nom anglais et le trigramme (si le trigramme n'est pas présent dans LISABR, le surligner en rouge) - trier la colonne "nom FR" de A à Z Si un Article n'est pas présent : - insérer une nouvelle ligne dans le tableau (Ctrl + "+") ou placer vous à la fin du tableau - renseigner l'article en français et son équivalent anglais - trier sur la colonne "nom FR" de A à Z
A19: Les feuilles "BIB" et "Type de table" sont des référentiels qui ne doivent pas être modifiés.
B20: Merci de notifier la cellule si une information est manquante.

Sheet Tables
A1: Nom du BIB | B1: Type table | C1: Objet de gestion 1 | D1: Objet de gestion 2 | E1: Objet de gestion 3 | F1: Objet de gestion 4 | G1: Robin | H1: Nb car | I1: Code | J1: Nom français | K1: Nom anglais | L1: Type
G2: =IF(ISBLANK(A2),"",LOOKUP(A2,BIB!A:A,BIB!C:C)) | H2: =IF(AND(ISBLANK(A2),ISBLANK(B2),ISBLANK(C2)),"",IF(OR(ISBLANK(A2),ISBLANK(B2),ISBLANK(C2)),"-",LEN(Tableau4[[#This Row],[Colonne9]]))) | I2: =IF(AND(ISBLANK(A2),ISBLANK(B2),ISBLANK(C2)),"",IF(OR(ISBLANK(A2),ISBLANK(B2),ISBLANK(C2)),"à compléter",UPPER(LOOKUP(A2,BIB!A:A,BIB!B:B)&LOOKUP(B2,'Type de table'!C:C,'Type de table'!B:B) &IF(COUNTIF('Objets de gestion'!C:C,F2)=0,"","_"&LOOKUP(F2,'Objets de gestion'!C:C,'Objets de gestion'!F:F)) &IF(COUNTIF('Objets de gestion'!C:C,E2)=0,"","_"&LOOKUP(E2,'Objets de gestion'!C:C,'Objets de gestion'!F:F)) &IF(COUNTIF('Objets de gestion'!C:C,D2)=0,"","_"&LOOKUP(D2,'Objets de gestion'!C:C,'Objets de gestion'!F:F)) &IF(COUNTIF('Objets de gestion'!C:C,C2)=0,"","_"&LOOKUP(C2,'Objets de gestion'!C:C,'Objets de gestion'!F:F)) ))) | J2: =IF(AND(ISBLANK(A2),ISBLANK(B2),ISBLANK(C2)),"",IF(OR(ISBLANK(A2),ISBLANK(B2),ISBLANK(C2)),"-", LOOKUP(B2,'Type de table'!C:C,'Type de table'!E:E) &IF(ISBLANK(C2),""," "&C2) &IF(ISBLANK(D2),""," "&D2) &IF(ISBLANK(E2),""," "&E2) &IF(ISBLANK(F2),""," "&F2) )) | K2: =IF(AND(ISBLANK(A2),ISBLANK(B2),ISBLANK(C2)),"",IF(OR(ISBLANK(A2),ISBLANK(B2),ISBLANK(C2)),"-", LOOKUP(B2,'Type de table'!C:C,'Type de table'!F:F) &IF(ISBLANK(C2),""," "&LOOKUP(C2,'Objets de gestion'!C:C,'Objets de gestion'!E:E)) &IF(ISBLANK(D2),""," "&LOOKUP(D2,'Objets de gestion'!C:C,'Objets de gestion'!E:E)) &IF(ISBLANK(E2),""," "&LOOKUP(E2,'Objets de gestion'!C:C,'Objets de gestion'!E:E)) &IF(ISBLANK(F2),""," "&LOOKUP(F2,'Objets de gestion'!C:C,'Objets de gestion'!E:E)) )) | L2: =IF(AND(ISBLANK(A2),ISBLANK(B2),ISBLANK(C2)),"",IF(OR(ISBLANK(A2),ISBLANK(B2),ISBLANK(C2)),"-",B2))
G3: =IF(ISBLANK(A3),"",LOOKUP(A3,BIB!A:A,BIB!C:C)) | H3: =IF(AND(ISBLANK(A3),ISBLANK(B3),ISBLANK(C3)),"",IF(OR(ISBLANK(A3),ISBLANK(B3),ISBLANK(C3)),"-",LEN(Tableau4[[#This Row],[Colonne9]]))) | I3: =IF(AND(ISBLANK(A3),ISBLANK(B3),ISBLANK(C3)),"",IF(OR(ISBLANK(A3),ISBLANK(B3),ISBLANK(C3)),"à compléter",UPPER(LOOKUP(A3,BIB!A:A,BIB!B:B)&LOOKUP(B3,'Type de table'!C:C,'Type de table'!B:B) &IF(COUNTIF('Objets de gestion'!C:C,F3)=0,"","_"&LOOKUP(F3,'Objets de gestion'!C:C,'Objets de gestion'!F:F)) &IF(COUNTIF('Objets de gestion'!C:C,E3)=0,"","_"&LOOKUP(E3,'Objets de gestion'!C:C,'Objets de gestion'!F:F)) &IF(COUNTIF('Objets de gestion'!C:C,D3)=0,"","_"&LOOKUP(D3,'Objets de gestion'!C:C,'Objets de gestion'!F:F)) &IF(COUNTIF('Objets de gestion'!C:C,C3)=0,"","_"&LOOKUP(C3,'Objets de gestion'!C:C,'Objets de gestion'!F:F)) ))) | J3: =IF(AND(ISBLANK(A3),ISBLANK(B3),ISBLANK(C3)),"",IF(OR(ISBLANK(A3),ISBLANK(B3),ISBLANK(C3)),"-", LOOKUP(B3,'Type de table'!C:C,'Type de table'!E:E) &IF(ISBLANK(C3),""," "&C3) &IF(ISBLANK(D3),""," "&D3) &IF(ISBLANK(E3),""," "&E3) &IF(ISBLANK(F3),""," "&F3) )) | K3: =IF(AND(ISBLANK(A3),ISBLANK(B3),ISBLANK(C3)),"",IF(OR(ISBLANK(A3),ISBLANK(B3),ISBLANK(C3)),"-", LOOKUP(B3,'Type de table'!C:C,'Type de table'!F:F) &IF(ISBLANK(C3),""," "&LOOKUP(C3,'Objets de gestion'!C:C,'Objets de gestion'!E:E)) &IF(ISBLANK(D3),""," "&LOOKUP(D3,'Objets de gestion'!C:C,'Objets de gestion'!E:E)) &IF(ISBLANK(E3),""," "&LOOKUP(E3,'Objets de gestion'!C:C,'Objets de gestion'!E:E)) &IF(ISBLANK(F3),""," "&LOOKUP(F3,'Objets de gestion'!C:C,'Objets de gestion'!E:E)) )) | L3: =IF(AND(ISBLANK(A3),ISBLANK(B3),ISBLANK(C3)),"",IF(OR(ISBLANK(A3),ISBLANK(B3),ISBLANK(C3)),"-",B3))
G4: =IF(ISBLANK(A4),"",LOOKUP(A4,BIB!A:A,BIB!C:C)) | H4: =IF(AND(ISBLANK(A4),ISBLANK(B4),ISBLANK(C4)),"",IF(OR(ISBLANK(A4),ISBLANK(B4),ISBLANK(C4)),"-",LEN(Tableau4[[#This Row],[Colonne9]]))) | I4: =IF(AND(ISBLANK(A4),ISBLANK(B4),ISBLANK(C4)),"",IF(OR(ISBLANK(A4),ISBLANK(B4),ISBLANK(C4)),"à compléter",UPPER(LOOKUP(A4,BIB!A:A,BIB!B:B)&LOOKUP(B4,'Type de table'!C:C,'Type de table'!B:B) &IF(COUNTIF('Objets de gestion'!C:C,F4)=0,"","_"&LOOKUP(F4,'Objets de gestion'!C:C,'Objets de gestion'!F:F)) &IF(COUNTIF('Objets de gestion'!C:C,E4)=0,"","_"&LOOKUP(E4,'Objets de gestion'!C:C,'Objets de gestion'!F:F)) &IF(COUNTIF('Objets de gestion'!C:C,D4)=0,"","_"&LOOKUP(D4,'Objets de gestion'!C:C,'Objets de gestion'!F:F)) &IF(COUNTIF('Objets de gestion'!C:C,C4)=0,"","_"&LOOKUP(C4,'Objets de gestion'!C:C,'Objets de gestion'!F:F)) ))) | J4: =IF(AND(ISBLANK(A4),ISBLANK(B4),ISBLANK(C4)),"",IF(OR(ISBLANK(A4),ISBLANK(B4),ISBLANK(C4)),"-", LOOKUP(B4,'Type de table'!C:C,'Type de table'!E:E) &IF(ISBLANK(C4),""," "&C4) &IF(ISBLANK(D4),""," "&D4) &IF(ISBLANK(E4),""," "&E4) &IF(ISBLANK(F4),""," "&F4) )) | K4: =IF(AND(ISBLANK(A4),ISBLANK(B4),ISBLANK(C4)),"",IF(OR(ISBLANK(A4),ISBLANK(B4),ISBLANK(C4)),"-", LOOKUP(B4,'Type de table'!C:C,'Type de table'!F:F) &IF(ISBLANK(C4),""," "&LOOKUP(C4,'Objets de gestion'!C:C,'Objets de gestion'!E:E)) &IF(ISBLANK(D4),""," "&LOOKUP(D4,'Objets de gestion'!C:C,'Objets de gestion'!E:E)) &IF(ISBLANK(E4),""," "&LOOKUP(E4,'Objets de gestion'!C:C,'Objets de gestion'!E:E)) &IF(ISBLANK(F4),""," "&LOOKUP(F4,'Objets de gestion'!C:C,'Objets de gestion'!E:E)) )) | L4: =IF(AND(ISBLANK(A4),ISBLANK(B4),ISBLANK(C4)),"",IF(OR(ISBLANK(A4),ISBLANK(B4),ISBLANK(C4)),"-",B4))
G5: =IF(ISBLANK(A5),"",LOOKUP(A5,BIB!A:A,BIB!C:C)) | H5: =IF(AND(ISBLANK(A5),ISBLANK(B5),ISBLANK(C5)),"",IF(OR(ISBLANK(A5),ISBLANK(B5),ISBLANK(C5)),"-",LEN(Tableau4[[#This Row],[Colonne9]]))) | I5: =IF(AND(ISBLANK(A5),ISBLANK(B5),ISBLANK(C5)),"",IF(OR(ISBLANK(A5),ISBLANK(B5),ISBLANK(C5)),"à compléter",UPPER(LOOKUP(A5,BIB!A:A,BIB!B:B)&LOOKUP(B5,'Type de table'!C:C,'Type de table'!B:B) &IF(COUNTIF('Objets de gestion'!C:C,F5)=0,"","_"&LOOKUP(F5,'Objets de gestion'!C:C,'Objets de gestion'!F:F)) &IF(COUNTIF('Objets de gestion'!C:C,E5)=0,"","_"&LOOKUP(E5,'Objets de gestion'!C:C,'Objets de gestion'!F:F)) &IF(COUNTIF('Objets de gestion'!C:C,D5)=0,"","_"&LOOKUP(D5,'Objets de gestion'!C:C,'Objets de gestion'!F:F)) &IF(COUNTIF('Objets de gestion'!C:C,C5)=0,"","_"&LOOKUP(C5,'Objets de gestion'!C:C,'Objets de gestion'!F:F)) ))) | J5: =IF(AND(ISBLANK(A5),ISBLANK(B5),ISBLANK(C5)),"",IF(OR(ISBLANK(A5),ISBLANK(B5),ISBLANK(C5)),"-", LOOKUP(B5,'Type de table'!C:C,'Type de table'!E:E) &IF(ISBLANK(C5),""," "&C5) &IF(ISBLANK(D5),""," "&D5) &IF(ISBLANK(E5),""," "&E5) &IF(ISBLANK(F5),""," "&F5) )) | K5: =IF(AND(ISBLANK(A5),ISBLANK(B5),ISBLANK(C5)),"",IF(OR(ISBLANK(A5),ISBLANK(B5),ISBLANK(C5)),"-", LOOKUP(B5,'Type de table'!C:C,'Type de table'!F:F) &IF(ISBLANK(C5),""," "&LOOKUP(C5,'Objets de gestion'!C:C,'Objets de gestion'!E:E)) &IF(ISBLANK(D5),""," "&LOOKUP(D5,'Objets de gestion'!C:C,'Objets de gestion'!E:E)) &IF(ISBLANK(E5),""," "&LOOKUP(E5,'Objets de gestion'!C:C,'Objets de gestion'!E:E)) &IF(ISBLANK(F5),""," "&LOOKUP(F5,'Objets de gestion'!C:C,'Objets de gestion'!E:E)) )) | L5: =IF(AND(ISBLANK(A5),ISBLANK(B5),ISBLANK(C5)),"",IF(OR(ISBLANK(A5),ISBLANK(B5),ISBLANK(C5)),"-",B5))
G6: =IF(ISBLANK(A6),"",LOOKUP(A6,BIB!A:A,BIB!C:C)) | H6: =IF(AND(ISBLANK(A6),ISBLANK(B6),ISBLANK(C6)),"",IF(OR(ISBLANK(A6),ISBLANK(B6),ISBLANK(C6)),"-",LEN(Tableau4[[#This Row],[Colonne9]]))) | I6: =IF(AND(ISBLANK(A6),ISBLANK(B6),ISBLANK(C6)),"",IF(OR(ISBLANK(A6),ISBLANK(B6),ISBLANK(C6)),"à compléter",UPPER(LOOKUP(A6,BIB!A:A,BIB!B:B)&LOOKUP(B6,'Type de table'!C:C,'Type de table'!B:B) &IF(COUNTIF('Objets de gestion'!C:C,F6)=0,"","_"&LOOKUP(F6,'Objets de gestion'!C:C,'Objets de gestion'!F:F)) &IF(COUNTIF('Objets de gestion'!C:C,E6)=0,"","_"&LOOKUP(E6,'Objets de gestion'!C:C,'Objets de gestion'!F:F)) &IF(COUNTIF('Objets de gestion'!C:C,D6)=0,"","_"&LOOKUP(D6,'Objets de gestion'!C:C,'Objets de gestion'!F:F)) &IF(COUNTIF('Objets de gestion'!C:C,C6)=0,"","_"&LOOKUP(C6,'Objets de gestion'!C:C,'Objets de gestion'!F:F)) ))) | J6: =IF(AND(ISBLANK(A6),ISBLANK(B6),ISBLANK(C6)),"",IF(OR(ISBLANK(A6),ISBLANK(B6),ISBLANK(C6)),"-", LOOKUP(B6,'Type de table'!C:C,'Type de table'!E:E) &IF(ISBLANK(C6),""," "&C6) &IF(ISBLANK(D6),""," "&D6) &IF(ISBLANK(E6),""," "&E6) &IF(ISBLANK(F6),""," "&F6) )) | K6: =IF(AND(ISBLANK(A6),ISBLANK(B6),ISBLANK(C6)),"",IF(OR(ISBLANK(A6),ISBLANK(B6),ISBLANK(C6)),"-", LOOKUP(B6,'Type de table'!C:C,'Type de table'!F:F) &IF(ISBLANK(C6),""," "&LOOKUP(C6,'Objets de gestion'!C:C,'Objets de gestion'!E:E)) &IF(ISBLANK(D6),""," "&LOOKUP(D6,'Objets de gestion'!C:C,'Objets de gestion'!E:E)) &IF(ISBLANK(E6),""," "&LOOKUP(E6,'Objets de gestion'!C:C,'Objets de gestion'!E:E)) &IF(ISBLANK(F6),""," "&LOOKUP(F6,'Objets de gestion'!C:C,'Objets de gestion'!E:E)) )) | L6: =IF(AND(ISBLANK(A6),ISBLANK(B6),ISBLANK(C6)),"",IF(OR(ISBLANK(A6),ISBLANK(B6),ISBLANK(C6)),"-",B6))
G7: =IF(ISBLANK(A7),"",LOOKUP(A7,BIB!A:A,BIB!C:C)) | H7: =IF(AND(ISBLANK(A7),ISBLANK(B7),ISBLANK(C7)),"",IF(OR(ISBLANK(A7),ISBLANK(B7),ISBLANK(C7)),"-",LEN(Tableau4[[#This Row],[Colonne9]]))) | I7: =IF(AND(ISBLANK(A7),ISBLANK(B7),ISBLANK(C7)),"",IF(OR(ISBLANK(A7),ISBLANK(B7),ISBLANK(C7)),"à compléter",UPPER(LOOKUP(A7,BIB!A:A,BIB!B:B)&LOOKUP(B7,'Type de table'!C:C,'Type de table'!B:B) &IF(COUNTIF('Objets de gestion'!C:C,F7)=0,"","_"&LOOKUP(F7,'Objets de gestion'!C:C,'Objets de gestion'!F:F)) &IF(COUNTIF('Objets de gestion'!C:C,E7)=0,"","_"&LOOKUP(E7,'Objets de gestion'!C:C,'Objets de gestion'!F:F)) &IF(COUNTIF('Objets de gestion'!C:C,D7)=0,"","_"&LOOKUP(D7,'Objets de gestion'!C:C,'Objets de gestion'!F:F)) &IF(COUNTIF('Objets de gestion'!C:C,C7)=0,"","_"&LOOKUP(C7,'Objets de gestion'!C:C,'Objets de gestion'!F:F)) ))) | J7: =IF(AND(ISBLANK(A7),ISBLANK(B7),ISBLANK(C7)),"",IF(OR(ISBLANK(A7),ISBLANK(B7),ISBLANK(C7)),"-", LOOKUP(B7,'Type de table'!C:C,'Type de table'!E:E) &IF(ISBLANK(C7),""," "&C7) &IF(ISBLANK(D7),""," "&D7) &IF(ISBLANK(E7),""," "&E7) &IF(ISBLANK(F7),""," "&F7) )) | K7: =IF(AND(ISBLANK(A7),ISBLANK(B7),ISBLANK(C7)),"",IF(OR(ISBLANK(A7),ISBLANK(B7),ISBLANK(C7)),"-", LOOKUP(B7,'Type de table'!C:C,'Type de table'!F:F) &IF(ISBLANK(C7),""," "&LOOKUP(C7,'Objets de gestion'!C:C,'Objets de gestion'!E:E)) &IF(ISBLANK(D7),""," "&LOOKUP(D7,'Objets de gestion'!C:C,'Objets de gestion'!E:E)) &IF(ISBLANK(E7),""," "&LOOKUP(E7,'Objets de gestion'!C:C,'Objets de gestion'!E:E)) &IF(ISBLANK(F7),""," "&LOOKUP(F7,'Objets de gestion'!C:C,'Objets de gestion'!E:E)) )) | L7: =IF(AND(ISBLANK(A7),ISBLANK(B7),ISBLANK(C7)),"",IF(OR(ISBLANK(A7),ISBLANK(B7),ISBLANK(C7)),"-",B7))
G8: =IF(ISBLANK(A8),"",LOOKUP(A8,BIB!A:A,BIB!C:C)) | H8: =IF(AND(ISBLANK(A8),ISBLANK(B8),ISBLANK(C8)),"",IF(OR(ISBLANK(A8),ISBLANK(B8),ISBLANK(C8)),"-",LEN(Tableau4[[#This Row],[Colonne9]]))) | I8: =IF(AND(ISBLANK(A8),ISBLANK(B8),ISBLANK(C8)),"",IF(OR(ISBLANK(A8),ISBLANK(B8),ISBLANK(C8)),"à compléter",UPPER(LOOKUP(A8,BIB!A:A,BIB!B:B)&LOOKUP(B8,'Type de table'!C:C,'Type de table'!B:B) &IF(COUNTIF('Objets de gestion'!C:C,F8)=0,"","_"&LOOKUP(F8,'Objets de gestion'!C:C,'Objets de gestion'!F:F)) &IF(COUNTIF('Objets de gestion'!C:C,E8)=0,"","_"&LOOKUP(E8,'Objets de gestion'!C:C,'Objets de gestion'!F:F)) &IF(COUNTIF('Objets de gestion'!C:C,D8)=0,"","_"&LOOKUP(D8,'Objets de gestion'!C:C,'Objets de gestion'!F:F)) &IF(COUNTIF('Objets de gestion'!C:C,C8)=0,"","_"&LOOKUP(C8,'Objets de gestion'!C:C,'Objets de gestion'!F:F)) ))) | J8: =IF(AND(ISBLANK(A8),ISBLANK(B8),ISBLANK(C8)),"",IF(OR(ISBLANK(A8),ISBLANK(B8),ISBLANK(C8)),"-", LOOKUP(B8,'Type de table'!C:C,'Type de table'!E:E) &IF(ISBLANK(C8),""," "&C8) &IF(ISBLANK(D8),""," "&D8) &IF(ISBLANK(E8),""," "&E8) &IF(ISBLANK(F8),""," "&F8) )) | K8: =IF(AND(ISBLANK(A8),ISBLANK(B8),ISBLANK(C8)),"",IF(OR(ISBLANK(A8),ISBLANK(B8),ISBLANK(C8)),"-", LOOKUP(B8,'Type de table'!C:C,'Type de table'!F:F) &IF(ISBLANK(C8),""," "&LOOKUP(C8,'Objets de gestion'!C:C,'Objets de gestion'!E:E)) &IF(ISBLANK(D8),""," "&LOOKUP(D8,'Objets de gestion'!C:C,'Objets de gestion'!E:E)) &IF(ISBLANK(E8),""," "&LOOKUP(E8,'Objets de gestion'!C:C,'Objets de gestion'!E:E)) &IF(ISBLANK(F8),""," "&LOOKUP(F8,'Objets de gestion'!C:C,'Objets de gestion'!E:E)) )) | L8: =IF(AND(ISBLANK(A8),ISBLANK(B8),ISBLANK(C8)),"",IF(OR(ISBLANK(A8),ISBLANK(B8),ISBLANK(C8)),"-",B8))
G9: =IF(ISBLANK(A9),"",LOOKUP(A9,BIB!A:A,BIB!C:C)) | H9: =IF(AND(ISBLANK(A9),ISBLANK(B9),ISBLANK(C9)),"",IF(OR(ISBLANK(A9),ISBLANK(B9),ISBLANK(C9)),"-",LEN(Tableau4[[#This Row],[Colonne9]]))) | I9: =IF(AND(ISBLANK(A9),ISBLANK(B9),ISBLANK(C9)),"",IF(OR(ISBLANK(A9),ISBLANK(B9),ISBLANK(C9)),"à compléter",UPPER(LOOKUP(A9,BIB!A:A,BIB!B:B)&LOOKUP(B9,'Type de table'!C:C,'Type de table'!B:B) &IF(COUNTIF('Objets de gestion'!C:C,F9)=0,"","_"&LOOKUP(F9,'Objets de gestion'!C:C,'Objets de gestion'!F:F)) &IF(COUNTIF('Objets de gestion'!C:C,E9)=0,"","_"&LOOKUP(E9,'Objets de gestion'!C:C,'Objets de gestion'!F:F)) &IF(COUNTIF('Objets de gestion'!C:C,D9)=0,"","_"&LOOKUP(D9,'Objets de gestion'!C:C,'Objets de gestion'!F:F)) &IF(COUNTIF('Objets de gestion'!C:C,C9)=0,"","_"&LOOKUP(C9,'Objets de gestion'!C:C,'Objets de gestion'!F:F)) ))) | J9: =IF(AND(ISBLANK(A9),ISBLANK(B9),ISBLANK(C9)),"",IF(OR(ISBLANK(A9),ISBLANK(B9),ISBLANK(C9)),"-", LOOKUP(B9,'Type de table'!C:C,'Type de table'!E:E) &IF(ISBLANK(C9),""," "&C9) &IF(ISBLANK(D9),""," "&D9) &IF(ISBLANK(E9),""," "&E9) &IF(ISBLANK(F9),""," "&F9) )) | K9: =IF(AND(ISBLANK(A9),ISBLANK(B9),ISBLANK(C9)),"",IF(OR(ISBLANK(A9),ISBLANK(B9),ISBLANK(C9)),"-", LOOKUP(B9,'Type de table'!C:C,'Type de table'!F:F) &IF(ISBLANK(C9),""," "&LOOKUP(C9,'Objets de gestion'!C:C,'Objets de gestion'!E:E)) &IF(ISBLANK(D9),""," "&LOOKUP(D9,'Objets de gestion'!C:C,'Objets de gestion'!E:E)) &IF(ISBLANK(E9),""," "&LOOKUP(E9,'Objets de gestion'!C:C,'Objets de gestion'!E:E)) &IF(ISBLANK(F9),""," "&LOOKUP(F9,'Objets de gestion'!C:C,'Objets de gestion'!E:E)) )) | L9: =IF(AND(ISBLANK(A9),ISBLANK(B9),ISBLANK(C9)),"",IF(OR(ISBLANK(A9),ISBLANK(B9),ISBLANK(C9)),"-",B9))
G10: =IF(ISBLANK(A10),"",LOOKUP(A10,BIB!A:A,BIB!C:C)) | H10: =IF(AND(ISBLANK(A10),ISBLANK(B10),ISBLANK(C10)),"",IF(OR(ISBLANK(A10),ISBLANK(B10),ISBLANK(C10)),"-",LEN(Tableau4[[#This Row],[Colonne9]]))) | I10: =IF(AND(ISBLANK(A10),ISBLANK(B10),ISBLANK(C10)),"",IF(OR(ISBLANK(A10),ISBLANK(B10),ISBLANK(C10)),"à compléter",UPPER(LOOKUP(A10,BIB!A:A,BIB!B:B)&LOOKUP(B10,'Type de table'!C:C,'Type de table'!B:B) &IF(COUNTIF('Objets de gestion'!C:C,F10)=0,"","_"&LOOKUP(F10,'Objets de gestion'!C:C,'Objets de gestion'!F:F)) &IF(COUNTIF('Objets de gestion'!C:C,E10)=0,"","_"&LOOKUP(E10,'Objets de gestion'!C:C,'Objets de gestion'!F:F)) &IF(COUNTIF('Objets de gestion'!C:C,D10)=0,"","_"&LOOKUP(D10,'Objets de gestion'!C:C,'Objets de gestion'!F:F)) &IF(COUNTIF('Objets de gestion'!C:C,C10)=0,"","_"&LOOKUP(C10,'Objets de gestion'!C:C,'Objets de gestion'!F:F)) ))) | J10: =IF(AND(ISBLANK(A10),ISBLANK(B10),ISBLANK(C10)),"",IF(OR(ISBLANK(A10),ISBLANK(B10),ISBLANK(C10)),"-", LOOKUP(B10,'Type de table'!C:C,'Type de table'!E:E) &IF(ISBLANK(C10),""," "&C10) &IF(ISBLANK(D10),""," "&D10) &IF(ISBLANK(E10),""," "&E10) &IF(ISBLANK(F10),""," "&F10) )) | K10: =IF(AND(ISBLANK(A10),ISBLANK(B10),ISBLANK(C10)),"",IF(OR(ISBLANK(A10),ISBLANK(B10),ISBLANK(C10)),"-", LOOKUP(B10,'Type de table'!C:C,'Type de table'!F:F) &IF(ISBLANK(C10),""," "&LOOKUP(C10,'Objets de gestion'!C:C,'Objets de gestion'!E:E)) &IF(ISBLANK(D10),""," "&LOOKUP(D10,'Objets de gestion'!C:C,'Objets de gestion'!E:E)) &IF(ISBLANK(E10),""," "&LOOKUP(E10,'Objets de gestion'!C:C,'Objets de gestion'!E:E)) &IF(ISBLANK(F10),""," "&LOOKUP(F10,'Objets de gestion'!C:C,'Objets de gestion'!E:E)) )) | L10: =IF(AND(ISBLANK(A10),ISBLANK(B10),ISBLANK(C10)),"",IF(OR(ISBLANK(A10),ISBLANK(B10),ISBLANK(C10)),"-",B10))
G11: =IF(ISBLANK(A11),"",LOOKUP(A11,BIB!A:A,BIB!C:C)) | H11: =IF(AND(ISBLANK(A11),ISBLANK(B11),ISBLANK(C11)),"",IF(OR(ISBLANK(A11),ISBLANK(B11),ISBLANK(C11)),"-",LEN(Tableau4[[#This Row],[Colonne9]]))) | I11: =IF(AND(ISBLANK(A11),ISBLANK(B11),ISBLANK(C11)),"",IF(OR(ISBLANK(A11),ISBLANK(B11),ISBLANK(C11)),"à compléter",UPPER(LOOKUP(A11,BIB!A:A,BIB!B:B)&LOOKUP(B11,'Type de table'!C:C,'Type de table'!B:B) &IF(COUNTIF('Objets de gestion'!C:C,F11)=0,"","_"&LOOKUP(F11,'Objets de gestion'!C:C,'Objets de gestion'!F:F)) &IF(COUNTIF('Objets de gestion'!C:C,E11)=0,"","_"&LOOKUP(E11,'Objets de gestion'!C:C,'Objets de gestion'!F:F)) &IF(COUNTIF('Objets de gestion'!C:C,D11)=0,"","_"&LOOKUP(D11,'Objets de gestion'!C:C,'Objets de gestion'!F:F)) &IF(COUNTIF('Objets de gestion'!C:C,C11)=0,"","_"&LOOKUP(C11,'Objets de gestion'!C:C,'Objets de gestion'!F:F)) ))) | J11: =IF(AND(ISBLANK(A11),ISBLANK(B11),ISBLANK(C11)),"",IF(OR(ISBLANK(A11),ISBLANK(B11),ISBLANK(C11)),"-", LOOKUP(B11,'Type de table'!C:C,'Type de table'!E:E) &IF(ISBLANK(C11),""," "&C11) &IF(ISBLANK(D11),""," "&D11) &IF(ISBLANK(E11),""," "&E11) &IF(ISBLANK(F11),""," "&F11) )) | K11: =IF(AND(ISBLANK(A11),ISBLANK(B11),ISBLANK(C11)),"",IF(OR(ISBLANK(A11),ISBLANK(B11),ISBLANK(C11)),"-", LOOKUP(B11,'Type de table'!C:C,'Type de table'!F:F) &IF(ISBLANK(C11),""," "&LOOKUP(C11,'Objets de gestion'!C:C,'Objets de gestion'!E:E)) &IF(ISBLANK(D11),""," "&LOOKUP(D11,'Objets de gestion'!C:C,'Objets de gestion'!E:E)) &IF(ISBLANK(E11),""," "&LOOKUP(E11,'Objets de gestion'!C:C,'Objets de gestion'!E:E)) &IF(ISBLANK(F11),""," "&LOOKUP(F11,'Objets de gestion'!C:C,'Objets de gestion'!E:E)) )) | L11: =IF(AND(ISBLANK(A11),ISBLANK(B11),ISBLANK(C11)),"",IF(OR(ISBLANK(A11),ISBLANK(B11),ISBLANK(C11)),"-",B11))
G12: =IF(ISBLANK(A12),"",LOOKUP(A12,BIB!A:A,BIB!C:C)) | H12: =IF(AND(ISBLANK(A12),ISBLANK(B12),ISBLANK(C12)),"",IF(OR(ISBLANK(A12),ISBLANK(B12),ISBLANK(C12)),"-",LEN(Tableau4[[#This Row],[Colonne9]]))) | I12: =IF(AND(ISBLANK(A12),ISBLANK(B12),ISBLANK(C12)),"",IF(OR(ISBLANK(A12),ISBLANK(B12),ISBLANK(C12)),"à compléter",UPPER(LOOKUP(A12,BIB!A:A,BIB!B:B)&LOOKUP(B12,'Type de table'!C:C,'Type de table'!B:B) &IF(COUNTIF('Objets de gestion'!C:C,F12)=0,"","_"&LOOKUP(F12,'Objets de gestion'!C:C,'Objets de gestion'!F:F)) &IF(COUNTIF('Objets de gestion'!C:C,E12)=0,"","_"&LOOKUP(E12,'Objets de gestion'!C:C,'Objets de gestion'!F:F)) &IF(COUNTIF('Objets de gestion'!C:C,D12)=0,"","_"&LOOKUP(D12,'Objets de gestion'!C:C,'Objets de gestion'!F:F)) &IF(COUNTIF('Objets de gestion'!C:C,C12)=0,"","_"&LOOKUP(C12,'Objets de gestion'!C:C,'Objets de gestion'!F:F)) ))) | J12: =IF(AND(ISBLANK(A12),ISBLANK(B12),ISBLANK(C12)),"",IF(OR(ISBLANK(A12),ISBLANK(B12),ISBLANK(C12)),"-", LOOKUP(B12,'Type de table'!C:C,'Type de table'!E:E) &IF(ISBLANK(C12),""," "&C12) &IF(ISBLANK(D12),""," "&D12) &IF(ISBLANK(E12),""," "&E12) &IF(ISBLANK(F12),""," "&F12) )) | K12: =IF(AND(ISBLANK(A12),ISBLANK(B12),ISBLANK(C12)),"",IF(OR(ISBLANK(A12),ISBLANK(B12),ISBLANK(C12)),"-", LOOKUP(B12,'Type de table'!C:C,'Type de table'!F:F) &IF(ISBLANK(C12),""," "&LOOKUP(C12,'Objets de gestion'!C:C,'Objets de gestion'!E:E)) &IF(ISBLANK(D12),""," "&LOOKUP(D12,'Objets de gestion'!C:C,'Objets de gestion'!E:E)) &IF(ISBLANK(E12),""," "&LOOKUP(E12,'Objets de gestion'!C:C,'Objets de gestion'!E:E)) &IF(ISBLANK(F12),""," "&LOOKUP(F12,'Objets de gestion'!C:C,'Objets de gestion'!E:E)) )) | L12: =IF(AND(ISBLANK(A12),ISBLANK(B12),ISBLANK(C12)),"",IF(OR(ISBLANK(A12),ISBLANK(B12),ISBLANK(C12)),"-",B12))
G13: =IF(ISBLANK(A13),"",LOOKUP(A13,BIB!A:A,BIB!C:C)) | H13: =IF(AND(ISBLANK(A13),ISBLANK(B13),ISBLANK(C13)),"",IF(OR(ISBLANK(A13),ISBLANK(B13),ISBLANK(C13)),"-",LEN(Tableau4[[#This Row],[Colonne9]]))) | I13: =IF(AND(ISBLANK(A13),ISBLANK(B13),ISBLANK(C13)),"",IF(OR(ISBLANK(A13),ISBLANK(B13),ISBLANK(C13)),"à compléter",UPPER(LOOKUP(A13,BIB!A:A,BIB!B:B)&LOOKUP(B13,'Type de table'!C:C,'Type de table'!B:B) &IF(COUNTIF('Objets de gestion'!C:C,F13)=0,"","_"&LOOKUP(F13,'Objets de gestion'!C:C,'Objets de gestion'!F:F)) &IF(COUNTIF('Objets de gestion'!C:C,E13)=0,"","_"&LOOKUP(E13,'Objets de gestion'!C:C,'Objets de gestion'!F:F)) &IF(COUNTIF('Objets de gestion'!C:C,D13)=0,"","_"&LOOKUP(D13,'Objets de gestion'!C:C,'Objets de gestion'!F:F)) &IF(COUNTIF('Objets de gestion'!C:C,C13)=0,"","_"&LOOKUP(C13,'Objets de gestion'!C:C,'Objets de gestion'!F:F)) ))) | J13: =IF(AND(ISBLANK(A13),ISBLANK(B13),ISBLANK(C13)),"",IF(OR(ISBLANK(A13),ISBLANK(B13),ISBLANK(C13)),"-", LOOKUP(B13,'Type de table'!C:C,'Type de table'!E:E) &IF(ISBLANK(C13),""," "&C13) &IF(ISBLANK(D13),""," "&D13) &IF(ISBLANK(E13),""," "&E13) &IF(ISBLANK(F13),""," "&F13) )) | K13: =IF(AND(ISBLANK(A13),ISBLANK(B13),ISBLANK(C13)),"",IF(OR(ISBLANK(A13),ISBLANK(B13),ISBLANK(C13)),"-", LOOKUP(B13,'Type de table'!C:C,'Type de table'!F:F) &IF(ISBLANK(C13),""," "&LOOKUP(C13,'Objets de gestion'!C:C,'Objets de gestion'!E:E)) &IF(ISBLANK(D13),""," "&LOOKUP(D13,'Objets de gestion'!C:C,'Objets de gestion'!E:E)) &IF(ISBLANK(E13),""," "&LOOKUP(E13,'Objets de gestion'!C:C,'Objets de gestion'!E:E)) &IF(ISBLANK(F13),""," "&LOOKUP(F13,'Objets de gestion'!C:C,'Objets de gestion'!E:E)) )) | L13: =IF(AND(ISBLANK(A13),ISBLANK(B13),ISBLANK(C13)),"",IF(OR(ISBLANK(A13),ISBLANK(B13),ISBLANK(C13)),"-",B13))
... G72: =IF(ISBLANK(A72),"",LOOKUP(A72,BIB!A:A,BIB!C:C)) | H72: =IF(AND(ISBLANK(A72),ISBLANK(B72),ISBLANK(C72)),"",IF(OR(ISBLANK(A72),ISBLANK(B72),ISBLANK(C72)),"-",LEN(Tableau4[[#This Row],[Colonne9]]))) | I72: =IF(AND(ISBLANK(A72),ISBLANK(B72),ISBLANK(C72)),"",IF(OR(ISBLANK(A72),ISBLANK(B72),ISBLANK(C72)),"à compléter",UPPER(LOOKUP(A72,BIB!A:A,BIB!B:B)&LOOKUP(B72,'Type de table'!C:C,'Type de table'!B:B) &IF(COUNTIF('Objets de gestion'!C:C,F72)=0,"","_"&LOOKUP(F72,'Objets de gestion'!C:C,'Objets de gestion'!F:F)) &IF(COUNTIF('Objets de gestion'!C:C,E72)=0,"","_"&LOOKUP(E72,'Objets de gestion'!C:C,'Objets de gestion'!F:F)) &IF(COUNTIF('Objets de gestion'!C:C,D72)=0,"","_"&LOOKUP(D72,'Objets de gestion'!C:C,'Objets de gestion'!F:F)) &IF(COUNTIF('Objets de gestion'!C:C,C72)=0,"","_"&LOOKUP(C72,'Objets de gestion'!C:C,'Objets de gestion'!F:F)) ))) | J72: =IF(AND(ISBLANK(A72),ISBLANK(B72),ISBLANK(C72)),"",IF(OR(ISBLANK(A72),ISBLANK(B72),ISBLANK(C72)),"-", LOOKUP(B72,'Type de table'!C:C,'Type de table'!E:E) &IF(ISBLANK(C72),""," "&C72) &IF(ISBLANK(D72),""," "&D72) &IF(ISBLANK(E72),""," "&E72) &IF(ISBLANK(F72),""," "&F72) )) | K72: =IF(AND(ISBLANK(A72),ISBLANK(B72),ISBLANK(C72)),"",IF(OR(ISBLANK(A72),ISBLANK(B72),ISBLANK(C72)),"-", LOOKUP(B72,'Type de table'!C:C,'Type de table'!F:F) &IF(ISBLANK(C72),""," "&LOOKUP(C72,'Objets de gestion'!C:C,'Objets de gestion'!E:E)) &IF(ISBLANK(D72),""," "&LOOKUP(D72,'Objets de gestion'!C:C,'Objets de gestion'!E:E)) &IF(ISBLANK(E72),""," "&LOOKUP(E72,'Objets de gestion'!C:C,'Objets de gestion'!E:E)) &IF(ISBLANK(F72),""," "&LOOKUP(F72,'Objets de gestion'!C:C,'Objets de gestion'!E:E)) )) | L72: =IF(AND(ISBLANK(A72),ISBLANK(B72),ISBLANK(C72)),"",IF(OR(ISBLANK(A72),ISBLANK(B72),ISBLANK(C72)),"-",B72))

Sheet Champs
A1: Nom du BIB | B1: Objet de gestion 1 | C1: article 1 | D1: Objet de gestion 2 | E1: article 2 | F1: Objet de gestion 3 | G1: article 3 | H1: Objet de gestion 4 | I1: Nb car | J1: Code | K1: Nom français | L1: Nom anglais | M1: Périmètre
A2: Acteur en assurance | B2: numéro | C2: d' | D2: ordre | I2: =IF(AND(ISBLANK(A2),ISBLANK(B2)),"",IF(OR(ISBLANK(A2),ISBLANK(B2)),"-",LEN(Tableau47[[#This Row],[Colonne9]]))) -> 7 | J2: =IF(AND(ISBLANK(A2),ISBLANK(B2)),"",IF(OR(ISBLANK(A2),ISBLANK(B2)),"à compléter", IF(H2=0,"",LOOKUP(H2,'Objets de gestion'!C:C,'Objets de gestion'!F:F)&"_") &IF(F2=0,"",LOOKUP(F2,'Objets de gestion'!C:C,'Objets de gestion'!F:F)&"_") &IF(D2=0,"",LOOKUP(D2,'Objets de gestion'!C:C,'Objets de gestion'!F:F)&"_") &IF(B2=0,"",LOOKUP(B2,'Objets de gestion'!C:C,'Objets de gestion'!F:F)) )) -> ORD_NBR | K2: =IF(AND(ISBLANK(A2),ISBLANK(B2)),"",IF(OR(ISBLANK(A2),ISBLANK(B2)),"-", B2&" "&IF(ISBLANK(D2),"",C2&" "&D2&" ")&IF(ISBLANK(F2),"",E2&" "&F2&" ")&IF(ISBLANK(H2),"",G2&" "&H2&" "))) -> numéro d' ordre | L2: =IF(AND(ISBLANK(A2),ISBLANK(B2)),"",IF(OR(ISBLANK(A2),ISBLANK(B2)),"-", IF(ISBLANK(B2),"",LOOKUP(B2,'Objets de gestion'!C:C,'Objets de gestion'!E:E)) &IF(ISBLANK(C2),""," "&LOOKUP(C2,Articles!A:A,Articles!B:B)) &IF(ISBLANK(D2),""," "&LOOKUP(D2,'Objets de gestion'!C:C,'Objets de gestion'!E:E)) &IF(ISBLANK(E2),""," "&LOOKUP(E2,Articles!A:A,Articles!B:B)) &IF(ISBLANK(F2),""," "&LOOKUP(F2,'Objets de gestion'!C:C,'Objets de gestion'!E:E)) &IF(ISBLANK(G2),""," "&LOOKUP(G2,Articles!A:A,Articles!B:B)) &IF(ISBLANK(H2),""," "&LOOKUP(H2,'Objets de gestion'!C:C,'Objets de gestion'!E:E)) )) -> number of the Order | M2: =IF(AND(ISBLANK(A2),ISBLANK(B2)),"",IF(OR(ISBLANK(A2),ISBLANK(B2)),"-", A2)) -> Acteur en assurance
A3: Acteur en assurance | B3: Date de début | C3: de | D3: cycle de vie | I3: =IF(AND(ISBLANK(A3),ISBLANK(B3)),"",IF(OR(ISBLANK(A3),ISBLANK(B3)),"-",LEN(Tableau47[[#This Row],[Colonne9]]))) -> 10 | J3: =IF(AND(ISBLANK(A3),ISBLANK(B3)),"",IF(OR(ISBLANK(A3),ISBLANK(B3)),"à compléter", IF(H3=0,"",LOOKUP(H3,'Objets de gestion'!C:C,'Objets de gestion'!F:F)&"_") &IF(F3=0,"",LOOKUP(F3,'Objets de gestion'!C:C,'Objets de gestion'!F:F)&"_") &IF(D3=0,"",LOOKUP(D3,'Objets de gestion'!C:C,'Objets de gestion'!F:F)&"_") &IF(B3=0,"",LOOKUP(B3,'Objets de gestion'!C:C,'Objets de gestion'!F:F)) )) -> LFC_STADAT | K3: =IF(AND(ISBLANK(A3),ISBLANK(B3)),"",IF(OR(ISBLANK(A3),ISBLANK(B3)),"-", B3&" "&IF(ISBLANK(D3),"",C3&" "&D3&" ")&IF(ISBLANK(F3),"",E3&" "&F3&" ")&IF(ISBLANK(H3),"",G3&" "&H3&" "))) -> Date de début de cycle de vie | L3: =IF(AND(ISBLANK(A3),ISBLANK(B3)),"",IF(OR(ISBLANK(A3),ISBLANK(B3)),"-", IF(ISBLANK(B3),"",LOOKUP(B3,'Objets de gestion'!C:C,'Objets de gestion'!E:E)) &IF(ISBLANK(C3),""," "&LOOKUP(C3,Articles!A:A,Articles!B:B)) &IF(ISBLANK(D3),""," "&LOOKUP(D3,'Objets de gestion'!C:C,'Objets de gestion'!E:E)) &IF(ISBLANK(E3),""," "&LOOKUP(E3,Articles!A:A,Articles!B:B)) &IF(ISBLANK(F3),""," "&LOOKUP(F3,'Objets de gestion'!C:C,'Objets de gestion'!E:E)) &IF(ISBLANK(G3),""," "&LOOKUP(G3,Articles!A:A,Articles!B:B)) &IF(ISBLANK(H3),""," "&LOOKUP(H3,'Objets de gestion'!C:C,'Objets de gestion'!E:E)) )) -> Start date of the lifecycle | M3: =IF(AND(ISBLANK(A3),ISBLANK(B3)),"",IF(OR(ISBLANK(A3),ISBLANK(B3)),"-", A3)) -> Acteur en assurance
A4: Acteur en assurance | B4: Date de fin | C4: de | D4: cycle de vie | I4: =IF(AND(ISBLANK(A4),ISBLANK(B4)),"",IF(OR(ISBLANK(A4),ISBLANK(B4)),"-",LEN(Tableau47[[#This Row],[Colonne9]]))) -> 10 | J4: =IF(AND(ISBLANK(A4),ISBLANK(B4)),"",IF(OR(ISBLANK(A4),ISBLANK(B4)),"à compléter", IF(H4=0,"",LOOKUP(H4,'Objets de gestion'!C:C,'Objets de gestion'!F:F)&"_") &IF(F4=0,"",LOOKUP(F4,'Objets de gestion'!C:C,'Objets de gestion'!F:F)&"_") &IF(D4=0,"",LOOKUP(D4,'Objets de gestion'!C:C,'Objets de gestion'!F:F)&"_") &IF(B4=0,"",LOOKUP(B4,'Objets de gestion'!C:C,'Objets de gestion'!F:F)) )) -> LFC_ENDDAT | K4: =IF(AND(ISBLANK(A4),ISBLANK(B4)),"",IF(OR(ISBLANK(A4),ISBLANK(B4)),"-", B4&" "&IF(ISBLANK(D4),"",C4&" "&D4&" ")&IF(ISBLANK(F4),"",E4&" "&F4&" ")&IF(ISBLANK(H4),"",G4&" "&H4&" "))) -> Date de fin de cycle de vie | L4: =IF(AND(ISBLANK(A4),ISBLANK(B4)),"",IF(OR(ISBLANK(A4),ISBLANK(B4)),"-", IF(ISBLANK(B4),"",LOOKUP(B4,'Objets de gestion'!C:C,'Objets de gestion'!E:E)) &IF(ISBLANK(C4),""," "&LOOKUP(C4,Articles!A:A,Articles!B:B)) &IF(ISBLANK(D4),""," "&LOOKUP(D4,'Objets de gestion'!C:C,'Objets de gestion'!E:E)) &IF(ISBLANK(E4),""," "&LOOKUP(E4,Articles!A:A,Articles!B:B)) &IF(ISBLANK(F4),""," "&LOOKUP(F4,'Objets de gestion'!C:C,'Objets de gestion'!E:E)) &IF(ISBLANK(G4),""," "&LOOKUP(G4,Articles!A:A,Articles!B:B)) &IF(ISBLANK(H4),""," "&LOOKUP(H4,'Objets de gestion'!C:C,'Objets de gestion'!E:E)) )) -> End date of the lifecycle | M4: =IF(AND(ISBLANK(A4),ISBLANK(B4)),"",IF(OR(ISBLANK(A4),ISBLANK(B4)),"-", A4)) -> Acteur en assurance
A5: Acteur en assurance | B5: code | C5: du | D5: produit | E5: du | F5: rôle | I5: =IF(AND(ISBLANK(A5),ISBLANK(B5)),"",IF(OR(ISBLANK(A5),ISBLANK(B5)),"-",LEN(Tableau47[[#This Row],[Colonne9]]))) -> 11 | J5: =IF(AND(ISBLANK(A5),ISBLANK(B5)),"",IF(OR(ISBLANK(A5),ISBLANK(B5)),"à compléter", IF(H5=0,"",LOOKUP(H5,'Objets de gestion'!C:C,'Objets de gestion'!F:F)&"_") &IF(F5=0,"",LOOKUP(F5,'Objets de gestion'!C:C,'Objets de gestion'!F:F)&"_") &IF(D5=0,"",LOOKUP(D5,'Objets de gestion'!C:C,'Objets de gestion'!F:F)&"_") &IF(B5=0,"",LOOKUP(B5,'Objets de gestion'!C:C,'Objets de gestion'!F:F)) )) -> ROL_PRD_COD | K5: =IF(AND(ISBLANK(A5),ISBLANK(B5)),"",IF(OR(ISBLANK(A5),ISBLANK(B5)),"-", B5&" "&IF(ISBLANK(D5),"",C5&" "&D5&" ")&IF(ISBLANK(F5),"",E5&" "&F5&" ")&IF(ISBLANK(H5),"",G5&" "&H5&" "))) -> code du produit du rôle | L5: =IF(AND(ISBLANK(A5),ISBLANK(B5)),"",IF(OR(ISBLANK(A5),ISBLANK(B5)),"-", IF(ISBLANK(B5),"",LOOKUP(B5,'Objets de gestion'!C:C,'Objets de gestion'!E:E)) &IF(ISBLANK(C5),""," "&LOOKUP(C5,Articles!A:A,Articles!B:B)) &IF(ISBLANK(D5),""," "&LOOKUP(D5,'Objets de gestion'!C:C,'Objets de gestion'!E:E)) &IF(ISBLANK(E5),""," "&LOOKUP(E5,Articles!A:A,Articles!B:B)) &IF(ISBLANK(F5),""," "&LOOKUP(F5,'Objets de gestion'!C:C,'Objets de gestion'!E:E)) &IF(ISBLANK(G5),""," "&LOOKUP(G5,Articles!A:A,Articles!B:B)) &IF(ISBLANK(H5),""," "&LOOKUP(H5,'Objets de gestion'!C:C,'Objets de gestion'!E:E)) )) -> code of the product of the role | M5: =IF(AND(ISBLANK(A5),ISBLANK(B5)),"",IF(OR(ISBLANK(A5),ISBLANK(B5)),"-", A5)) -> Acteur en assurance
A6: Acteur en assurance | B6: CCN | I6: =IF(AND(ISBLANK(A6),ISBLANK(B6)),"",IF(OR(ISBLANK(A6),ISBLANK(B6)),"-",LEN(Tableau47[[#This Row],[Colonne9]]))) -> 3 | J6: =IF(AND(ISBLANK(A6),ISBLANK(B6)),"",IF(OR(ISBLANK(A6),ISBLANK(B6)),"à compléter", IF(H6=0,"",LOOKUP(H6,'Objets de gestion'!C:C,'Objets de gestion'!F:F)&"_") &IF(F6=0,"",LOOKUP(F6,'Objets de gestion'!C:C,'Objets de gestion'!F:F)&"_") &IF(D6=0,"",LOOKUP(D6,'Objets de gestion'!C:C,'Objets de gestion'!F:F)&"_") &IF(B6=0,"",LOOKUP(B6,'Objets de gestion'!C:C,'Objets de gestion'!F:F)) )) -> CCN | K6: =IF(AND(ISBLANK(A6),ISBLANK(B6)),"",IF(OR(ISBLANK(A6),ISBLANK(B6)),"-", B6&" "&IF(ISBLANK(D6),"",C6&" "&D6&" ")&IF(ISBLANK(F6),"",E6&" "&F6&" ")&IF(ISBLANK(H6),"",G6&" "&H6&" "))) -> CCN | L6: =IF(AND(ISBLANK(A6),ISBLANK(B6)),"",IF(OR(ISBLANK(A6),ISBLANK(B6)),"-", IF(ISBLANK(B6),"",LOOKUP(B6,'Objets de gestion'!C:C,'Objets de gestion'!E:E)) &IF(ISBLANK(C6),""," "&LOOKUP(C6,Articles!A:A,Articles!B:B)) &IF(ISBLANK(D6),""," "&LOOKUP(D6,'Objets de gestion'!C:C,'Objets de gestion'!E:E)) &IF(ISBLANK(E6),""," "&LOOKUP(E6,Articles!A:A,Articles!B:B)) &IF(ISBLANK(F6),""," "&LOOKUP(F6,'Objets de gestion'!C:C,'Objets de gestion'!E:E)) &IF(ISBLANK(G6),""," "&LOOKUP(G6,Articles!A:A,Articles!B:B)) &IF(ISBLANK(H6),""," "&LOOKUP(H6,'Objets de gestion'!C:C,'Objets de gestion'!E:E)) )) -> CCN | M6: =IF(AND(ISBLANK(A6),ISBLANK(B6)),"",IF(OR(ISBLANK(A6),ISBLANK(B6)),"-", A6)) -> Acteur en assurance
A7: Acteur en assurance | B7: saisonnalité des tiers moraux | I7: =IF(AND(ISBLANK(A7),ISBLANK(B7)),"",IF(OR(ISBLANK(A7),ISBLANK(B7)),"-",LEN(Tableau47[[#This Row],[Colonne9]]))) -> 6 | J7: =IF(AND(ISBLANK(A7),ISBLANK(B7)),"",IF(OR(ISBLANK(A7),ISBLANK(B7)),"à compléter", IF(H7=0,"",LOOKUP(H7,'Objets de gestion'!C:C,'Objets de gestion'!F:F)&"_") &IF(F7=0,"",LOOKUP(F7,'Objets de gestion'!C:C,'Objets de gestion'!F:F)&"_") &IF(D7=0,"",LOOKUP(D7,'Objets de gestion'!C:C,'Objets de gestion'!F:F)&"_") &IF(B7=0,"",LOOKUP(B7,'Objets de gestion'!C:C,'Objets de gestion'!F:F)) )) -> SEASTM | K7: =IF(AND(ISBLANK(A7),ISBLANK(B7)),"",IF(OR(ISBLANK(A7),ISBLANK(B7)),"-", B7&" "&IF(ISBLANK(D7),"",C7&" "&D7&" ")&IF(ISBLANK(F7),"",E7&" "&F7&" ")&IF(ISBLANK(H7),"",G7&" "&H7&" "))) -> saisonnalité des tiers moraux | L7: =IF(AND(ISBLANK(A7),ISBLANK(B7)),"",IF(OR(ISBLANK(A7),ISBLANK(B7)),"-", IF(ISBLANK(B7),"",LOOKUP(B7,'Objets de gestion'!C:C,'Objets de gestion'!E:E)) &IF(ISBLANK(C7),""," "&LOOKUP(C7,Articles!A:A,Articles!B:B)) &IF(ISBLANK(D7),""," "&LOOKUP(D7,'Objets de gestion'!C:C,'Objets de gestion'!E:E)) &IF(ISBLANK(E7),""," "&LOOKUP(E7,Articles!A:A,Articles!B:B)) &IF(ISBLANK(F7),""," "&LOOKUP(F7,'Objets de gestion'!C:C,'Objets de gestion'!E:E)) &IF(ISBLANK(G7),""," "&LOOKUP(G7,Articles!A:A,Articles!B:B)) &IF(ISBLANK(H7),""," "&LOOKUP(H7,'Objets de gestion'!C:C,'Objets de gestion'!E:E)) )) -> seasonality of moral third parties | M7: =IF(AND(ISBLANK(A7),ISBLANK(B7)),"",IF(OR(ISBLANK(A7),ISBLANK(B7)),"-", A7)) -> Acteur en assurance
I8: =IF(AND(ISBLANK(A8),ISBLANK(B8)),"",IF(OR(ISBLANK(A8),ISBLANK(B8)),"-",LEN(Tableau47[[#This Row],[Colonne9]]))) | J8: =IF(AND(ISBLANK(A8),ISBLANK(B8)),"",IF(OR(ISBLANK(A8),ISBLANK(B8)),"à compléter", IF(H8=0,"",LOOKUP(H8,'Objets de gestion'!C:C,'Objets de gestion'!F:F)&"_") &IF(F8=0,"",LOOKUP(F8,'Objets de gestion'!C:C,'Objets de gestion'!F:F)&"_") &IF(D8=0,"",LOOKUP(D8,'Objets de gestion'!C:C,'Objets de gestion'!F:F)&"_") &IF(B8=0,"",LOOKUP(B8,'Objets de gestion'!C:C,'Objets de gestion'!F:F)) )) | K8: =IF(AND(ISBLANK(A8),ISBLANK(B8)),"",IF(OR(ISBLANK(A8),ISBLANK(B8)),"-", B8&" "&IF(ISBLANK(D8),"",C8&" "&D8&" ")&IF(ISBLANK(F8),"",E8&" "&F8&" ")&IF(ISBLANK(H8),"",G8&" "&H8&" "))) | L8: =IF(AND(ISBLANK(A8),ISBLANK(B8)),"",IF(OR(ISBLANK(A8),ISBLANK(B8)),"-", IF(ISBLANK(B8),"",LOOKUP(B8,'Objets de gestion'!C:C,'Objets de gestion'!E:E)) &IF(ISBLANK(C8),""," "&LOOKUP(C8,Articles!A:A,Articles!B:B)) &IF(ISBLANK(D8),""," "&LOOKUP(D8,'Objets de gestion'!C:C,'Objets de gestion'!E:E)) &IF(ISBLANK(E8),""," "&LOOKUP(E8,Articles!A:A,Articles!B:B)) &IF(ISBLANK(F8),""," "&LOOKUP(F8,'Objets de gestion'!C:C,'Objets de gestion'!E:E)) &IF(ISBLANK(G8),""," "&LOOKUP(G8,Articles!A:A,Articles!B:B)) &IF(ISBLANK(H8),""," "&LOOKUP(H8,'Objets de gestion'!C:C,'Objets de gestion'!E:E)) )) | M8: =IF(AND(ISBLANK(A8),ISBLANK(B8)),"",IF(OR(ISBLANK(A8),ISBLANK(B8)),"-", A8))
I9: =IF(AND(ISBLANK(A9),ISBLANK(B9)),"",IF(OR(ISBLANK(A9),ISBLANK(B9)),"-",LEN(Tableau47[[#This Row],[Colonne9]]))) | J9: =IF(AND(ISBLANK(A9),ISBLANK(B9)),"",IF(OR(ISBLANK(A9),ISBLANK(B9)),"à compléter", IF(H9=0,"",LOOKUP(H9,'Objets de gestion'!C:C,'Objets de gestion'!F:F)&"_") &IF(F9=0,"",LOOKUP(F9,'Objets de gestion'!C:C,'Objets de gestion'!F:F)&"_") &IF(D9=0,"",LOOKUP(D9,'Objets de gestion'!C:C,'Objets de gestion'!F:F)&"_") &IF(B9=0,"",LOOKUP(B9,'Objets de gestion'!C:C,'Objets de gestion'!F:F)) )) | K9: =IF(AND(ISBLANK(A9),ISBLANK(B9)),"",IF(OR(ISBLANK(A9),ISBLANK(B9)),"-", B9&" "&IF(ISBLANK(D9),"",C9&" "&D9&" ")&IF(ISBLANK(F9),"",E9&" "&F9&" ")&IF(ISBLANK(H9),"",G9&" "&H9&" "))) | L9: =IF(AND(ISBLANK(A9),ISBLANK(B9)),"",IF(OR(ISBLANK(A9),ISBLANK(B9)),"-", IF(ISBLANK(B9),"",LOOKUP(B9,'Objets de gestion'!C:C,'Objets de gestion'!E:E)) &IF(ISBLANK(C9),""," "&LOOKUP(C9,Articles!A:A,Articles!B:B)) &IF(ISBLANK(D9),""," "&LOOKUP(D9,'Objets de gestion'!C:C,'Objets de gestion'!E:E)) &IF(ISBLANK(E9),""," "&LOOKUP(E9,Articles!A:A,Articles!B:B)) &IF(ISBLANK(F9),""," "&LOOKUP(F9,'Objets de gestion'!C:C,'Objets de gestion'!E:E)) &IF(ISBLANK(G9),""," "&LOOKUP(G9,Articles!A:A,Articles!B:B)) &IF(ISBLANK(H9),""," "&LOOKUP(H9,'Objets de gestion'!C:C,'Objets de gestion'!E:E)) )) | M9: =IF(AND(ISBLANK(A9),ISBLANK(B9)),"",IF(OR(ISBLANK(A9),ISBLANK(B9)),"-", A9))
I10: =IF(AND(ISBLANK(A10),ISBLANK(B10)),"",IF(OR(ISBLANK(A10),ISBLANK(B10)),"-",LEN(Tableau47[[#This Row],[Colonne9]]))) | J10: =IF(AND(ISBLANK(A10),ISBLANK(B10)),"",IF(OR(ISBLANK(A10),ISBLANK(B10)),"à compléter", IF(H10=0,"",LOOKUP(H10,'Objets de gestion'!C:C,'Objets de gestion'!F:F)&"_") &IF(F10=0,"",LOOKUP(F10,'Objets de gestion'!C:C,'Objets de gestion'!F:F)&"_") &IF(D10=0,"",LOOKUP(D10,'Objets de gestion'!C:C,'Objets de gestion'!F:F)&"_") &IF(B10=0,"",LOOKUP(B10,'Objets de gestion'!C:C,'Objets de gestion'!F:F)) )) | K10: =IF(AND(ISBLANK(A10),ISBLANK(B10)),"",IF(OR(ISBLANK(A10),ISBLANK(B10)),"-", B10&" "&IF(ISBLANK(D10),"",C10&" "&D10&" ")&IF(ISBLANK(F10),"",E10&" "&F10&" ")&IF(ISBLANK(H10),"",G10&" "&H10&" "))) | L10: =IF(AND(ISBLANK(A10),ISBLANK(B10)),"",IF(OR(ISBLANK(A10),ISBLANK(B10)),"-", IF(ISBLANK(B10),"",LOOKUP(B10,'Objets de gestion'!C:C,'Objets de gestion'!E:E)) &IF(ISBLANK(C10),""," "&LOOKUP(C10,Articles!A:A,Articles!B:B)) &IF(ISBLANK(D10),""," "&LOOKUP(D10,'Objets de gestion'!C:C,'Objets de gestion'!E:E)) &IF(ISBLANK(E10),""," "&LOOKUP(E10,Articles!A:A,Articles!B:B)) &IF(ISBLANK(F10),""," "&LOOKUP(F10,'Objets de gestion'!C:C,'Objets de gestion'!E:E)) &IF(ISBLANK(G10),""," "&LOOKUP(G10,Articles!A:A,Articles!B:B)) &IF(ISBLANK(H10),""," "&LOOKUP(H10,'Objets de gestion'!C:C,'Objets de gestion'!E:E)) )) | M10: =IF(AND(ISBLANK(A10),ISBLANK(B10)),"",IF(OR(ISBLANK(A10),ISBLANK(B10)),"-", A10))
I11: =IF(AND(ISBLANK(A11),ISBLANK(B11)),"",IF(OR(ISBLANK(A11),ISBLANK(B11)),"-",LEN(Tableau47[[#This Row],[Colonne9]]))) | J11: =IF(AND(ISBLANK(A11),ISBLANK(B11)),"",IF(OR(ISBLANK(A11),ISBLANK(B11)),"à compléter", IF(H11=0,"",LOOKUP(H11,'Objets de gestion'!C:C,'Objets de gestion'!F:F)&"_") &IF(F11=0,"",LOOKUP(F11,'Objets de gestion'!C:C,'Objets de gestion'!F:F)&"_") &IF(D11=0,"",LOOKUP(D11,'Objets de gestion'!C:C,'Objets de gestion'!F:F)&"_") &IF(B11=0,"",LOOKUP(B11,'Objets de gestion'!C:C,'Objets de gestion'!F:F)) )) | K11: =IF(AND(ISBLANK(A11),ISBLANK(B11)),"",IF(OR(ISBLANK(A11),ISBLANK(B11)),"-", B11&" "&IF(ISBLANK(D11),"",C11&" "&D11&" ")&IF(ISBLANK(F11),"",E11&" "&F11&" ")&IF(ISBLANK(H11),"",G11&" "&H11&" "))) | L11: =IF(AND(ISBLANK(A11),ISBLANK(B11)),"",IF(OR(ISBLANK(A11),ISBLANK(B11)),"-", IF(ISBLANK(B11),"",LOOKUP(B11,'Objets de gestion'!C:C,'Objets de gestion'!E:E)) &IF(ISBLANK(C11),""," "&LOOKUP(C11,Articles!A:A,Articles!B:B)) &IF(ISBLANK(D11),""," "&LOOKUP(D11,'Objets de gestion'!C:C,'Objets de gestion'!E:E)) &IF(ISBLANK(E11),""," "&LOOKUP(E11,Articles!A:A,Articles!B:B)) &IF(ISBLANK(F11),""," "&LOOKUP(F11,'Objets de gestion'!C:C,'Objets de gestion'!E:E)) &IF(ISBLANK(G11),""," "&LOOKUP(G11,Articles!A:A,Articles!B:B)) &IF(ISBLANK(H11),""," "&LOOKUP(H11,'Objets de gestion'!C:C,'Objets de gestion'!E:E)) )) | M11: =IF(AND(ISBLANK(A11),ISBLANK(B11)),"",IF(OR(ISBLANK(A11),ISBLANK(B11)),"-", A11))
I12: =IF(AND(ISBLANK(A12),ISBLANK(B12)),"",IF(OR(ISBLANK(A12),ISBLANK(B12)),"-",LEN(Tableau47[[#This Row],[Colonne9]]))) | J12: =IF(AND(ISBLANK(A12),ISBLANK(B12)),"",IF(OR(ISBLANK(A12),ISBLANK(B12)),"à compléter", IF(H12=0,"",LOOKUP(H12,'Objets de gestion'!C:C,'Objets de gestion'!F:F)&"_") &IF(F12=0,"",LOOKUP(F12,'Objets de gestion'!C:C,'Objets de gestion'!F:F)&"_") &IF(D12=0,"",LOOKUP(D12,'Objets de gestion'!C:C,'Objets de gestion'!F:F)&"_") &IF(B12=0,"",LOOKUP(B12,'Objets de gestion'!C:C,'Objets de gestion'!F:F)) )) | K12: =IF(AND(ISBLANK(A12),ISBLANK(B12)),"",IF(OR(ISBLANK(A12),ISBLANK(B12)),"-", B12&" "&IF(ISBLANK(D12),"",C12&" "&D12&" ")&IF(ISBLANK(F12),"",E12&" "&F12&" ")&IF(ISBLANK(H12),"",G12&" "&H12&" "))) | L12: =IF(AND(ISBLANK(A12),ISBLANK(B12)),"",IF(OR(ISBLANK(A12),ISBLANK(B12)),"-", IF(ISBLANK(B12),"",LOOKUP(B12,'Objets de gestion'!C:C,'Objets de gestion'!E:E)) &IF(ISBLANK(C12),""," "&LOOKUP(C12,Articles!A:A,Articles!B:B)) &IF(ISBLANK(D12),""," "&LOOKUP(D12,'Objets de gestion'!C:C,'Objets de gestion'!E:E)) &IF(ISBLANK(E12),""," "&LOOKUP(E12,Articles!A:A,Articles!B:B)) &IF(ISBLANK(F12),""," "&LOOKUP(F12,'Objets de gestion'!C:C,'Objets de gestion'!E:E)) &IF(ISBLANK(G12),""," "&LOOKUP(G12,Articles!A:A,Articles!B:B)) &IF(ISBLANK(H12),""," "&LOOKUP(H12,'Objets de gestion'!C:C,'Objets de gestion'!E:E)) )) | M12: =IF(AND(ISBLANK(A12),ISBLANK(B12)),"",IF(OR(ISBLANK(A12),ISBLANK(B12)),"-", A12))
I13: =IF(AND(ISBLANK(A13),ISBLANK(B13)),"",IF(OR(ISBLANK(A13),ISBLANK(B13)),"-",LEN(Tableau47[[#This Row],[Colonne9]]))) | J13: =IF(AND(ISBLANK(A13),ISBLANK(B13)),"",IF(OR(ISBLANK(A13),ISBLANK(B13)),"à compléter", IF(H13=0,"",LOOKUP(H13,'Objets de gestion'!C:C,'Objets de gestion'!F:F)&"_") &IF(F13=0,"",LOOKUP(F13,'Objets de gestion'!C:C,'Objets de gestion'!F:F)&"_") &IF(D13=0,"",LOOKUP(D13,'Objets de gestion'!C:C,'Objets de gestion'!F:F)&"_") &IF(B13=0,"",LOOKUP(B13,'Objets de gestion'!C:C,'Objets de gestion'!F:F)) )) | K13: =IF(AND(ISBLANK(A13),ISBLANK(B13)),"",IF(OR(ISBLANK(A13),ISBLANK(B13)),"-", B13&" "&IF(ISBLANK(D13),"",C13&" "&D13&" ")&IF(ISBLANK(F13),"",E13&" "&F13&" ")&IF(ISBLANK(H13),"",G13&" "&H13&" "))) | L13: =IF(AND(ISBLANK(A13),ISBLANK(B13)),"",IF(OR(ISBLANK(A13),ISBLANK(B13)),"-", IF(ISBLANK(B13),"",LOOKUP(B13,'Objets de gestion'!C:C,'Objets de gestion'!E:E)) &IF(ISBLANK(C13),""," "&LOOKUP(C13,Articles!A:A,Articles!B:B)) &IF(ISBLANK(D13),""," "&LOOKUP(D13,'Objets de gestion'!C:C,'Objets de gestion'!E:E)) &IF(ISBLANK(E13),""," "&LOOKUP(E13,Articles!A:A,Articles!B:B)) &IF(ISBLANK(F13),""," "&LOOKUP(F13,'Objets de gestion'!C:C,'Objets de gestion'!E:E)) &IF(ISBLANK(G13),""," "&LOOKUP(G13,Articles!A:A,Articles!B:B)) &IF(ISBLANK(H13),""," "&LOOKUP(H13,'Objets de gestion'!C:C,'Objets de gestion'!E:E)) )) | M13: =IF(AND(ISBLANK(A13),ISBLANK(B13)),"",IF(OR(ISBLANK(A13),ISBLANK(B13)),"-", A13))
I14: =IF(AND(ISBLANK(A14),ISBLANK(B14)),"",IF(OR(ISBLANK(A14),ISBLANK(B14)),"-",LEN(Tableau47[[#This Row],[Colonne9]]))) | J14: =IF(AND(ISBLANK(A14),ISBLANK(B14)),"",IF(OR(ISBLANK(A14),ISBLANK(B14)),"à compléter", IF(H14=0,"",LOOKUP(H14,'Objets de gestion'!C:C,'Objets de gestion'!F:F)&"_") &IF(F14=0,"",LOOKUP(F14,'Objets de gestion'!C:C,'Objets de gestion'!F:F)&"_") &IF(D14=0,"",LOOKUP(D14,'Objets de gestion'!C:C,'Objets de gestion'!F:F)&"_") &IF(B14=0,"",LOOKUP(B14,'Objets de gestion'!C:C,'Objets de gestion'!F:F)) )) | K14: =IF(AND(ISBLANK(A14),ISBLANK(B14)),"",IF(OR(ISBLANK(A14),ISBLANK(B14)),"-", B14&" "&IF(ISBLANK(D14),"",C14&" "&D14&" ")&IF(ISBLANK(F14),"",E14&" "&F14&" ")&IF(ISBLANK(H14),"",G14&" "&H14&" "))) | L14: =IF(AND(ISBLANK(A14),ISBLANK(B14)),"",IF(OR(ISBLANK(A14),ISBLANK(B14)),"-", IF(ISBLANK(B14),"",LOOKUP(B14,'Objets de gestion'!C:C,'Objets de gestion'!E:E)) &IF(ISBLANK(C14),""," "&LOOKUP(C14,Articles!A:A,Articles!B:B)) &IF(ISBLANK(D14),""," "&LOOKUP(D14,'Objets de gestion'!C:C,'Objets de gestion'!E:E)) &IF(ISBLANK(E14),""," "&LOOKUP(E14,Articles!A:A,Articles!B:B)) &IF(ISBLANK(F14),""," "&LOOKUP(F14,'Objets de gestion'!C:C,'Objets de gestion'!E:E)) &IF(ISBLANK(G14),""," "&LOOKUP(G14,Articles!A:A,Articles!B:B)) &IF(ISBLANK(H14),""," "&LOOKUP(H14,'Objets de gestion'!C:C,'Objets de gestion'!E:E)) )) | M14: =IF(AND(ISBLANK(A14),ISBLANK(B14)),"",IF(OR(ISBLANK(A14),ISBLANK(B14)),"-", A14))
I15: =IF(AND(ISBLANK(A15),ISBLANK(B15)),"",IF(OR(ISBLANK(A15),ISBLANK(B15)),"-",LEN(Tableau47[[#This Row],[Colonne9]]))) | J15: =IF(AND(ISBLANK(A15),ISBLANK(B15)),"",IF(OR(ISBLANK(A15),ISBLANK(B15)),"à compléter", IF(H15=0,"",LOOKUP(H15,'Objets de gestion'!C:C,'Objets de gestion'!F:F)&"_") &IF(F15=0,"",LOOKUP(F15,'Objets de gestion'!C:C,'Objets de gestion'!F:F)&"_") &IF(D15=0,"",LOOKUP(D15,'Objets de gestion'!C:C,'Objets de gestion'!F:F)&"_") &IF(B15=0,"",LOOKUP(B15,'Objets de gestion'!C:C,'Objets de gestion'!F:F)) )) | K15: =IF(AND(ISBLANK(A15),ISBLANK(B15)),"",IF(OR(ISBLANK(A15),ISBLANK(B15)),"-", B15&" "&IF(ISBLANK(D15),"",C15&" "&D15&" ")&IF(ISBLANK(F15),"",E15&" "&F15&" ")&IF(ISBLANK(H15),"",G15&" "&H15&" "))) | L15: =IF(AND(ISBLANK(A15),ISBLANK(B15)),"",IF(OR(ISBLANK(A15),ISBLANK(B15)),"-", IF(ISBLANK(B15),"",LOOKUP(B15,'Objets de gestion'!C:C,'Objets de gestion'!E:E)) &IF(ISBLANK(C15),""," "&LOOKUP(C15,Articles!A:A,Articles!B:B)) &IF(ISBLANK(D15),""," "&LOOKUP(D15,'Objets de gestion'!C:C,'Objets de gestion'!E:E)) &IF(ISBLANK(E15),""," "&LOOKUP(E15,Articles!A:A,Articles!B:B)) &IF(ISBLANK(F15),""," "&LOOKUP(F15,'Objets de gestion'!C:C,'Objets de gestion'!E:E)) &IF(ISBLANK(G15),""," "&LOOKUP(G15,Articles!A:A,Articles!B:B)) &IF(ISBLANK(H15),""," "&LOOKUP(H15,'Objets de gestion'!C:C,'Objets de gestion'!E:E)) )) | M15: =IF(AND(ISBLANK(A15),ISBLANK(B15)),"",IF(OR(ISBLANK(A15),ISBLANK(B15)),"-", A15))
I16: =IF(AND(ISBLANK(A16),ISBLANK(B16)),"",IF(OR(ISBLANK(A16),ISBLANK(B16)),"-",LEN(Tableau47[[#This Row],[Colonne9]]))) | J16: =IF(AND(ISBLANK(A16),ISBLANK(B16)),"",IF(OR(ISBLANK(A16),ISBLANK(B16)),"à compléter", IF(H16=0,"",LOOKUP(H16,'Objets de gestion'!C:C,'Objets de gestion'!F:F)&"_") &IF(F16=0,"",LOOKUP(F16,'Objets de gestion'!C:C,'Objets de gestion'!F:F)&"_") &IF(D16=0,"",LOOKUP(D16,'Objets de gestion'!C:C,'Objets de gestion'!F:F)&"_") &IF(B16=0,"",LOOKUP(B16,'Objets de gestion'!C:C,'Objets de gestion'!F:F)) )) | K16: =IF(AND(ISBLANK(A16),ISBLANK(B16)),"",IF(OR(ISBLANK(A16),ISBLANK(B16)),"-", B16&" "&IF(ISBLANK(D16),"",C16&" "&D16&" ")&IF(ISBLANK(F16),"",E16&" "&F16&" ")&IF(ISBLANK(H16),"",G16&" "&H16&" "))) | L16: =IF(AND(ISBLANK(A16),ISBLANK(B16)),"",IF(OR(ISBLANK(A16),ISBLANK(B16)),"-", IF(ISBLANK(B16),"",LOOKUP(B16,'Objets de gestion'!C:C,'Objets de gestion'!E:E)) &IF(ISBLANK(C16),""," "&LOOKUP(C16,Articles!A:A,Articles!B:B)) &IF(ISBLANK(D16),""," "&LOOKUP(D16,'Objets de gestion'!C:C,'Objets de gestion'!E:E)) &IF(ISBLANK(E16),""," "&LOOKUP(E16,Articles!A:A,Articles!B:B)) &IF(ISBLANK(F16),""," "&LOOKUP(F16,'Objets de gestion'!C:C,'Objets de gestion'!E:E)) &IF(ISBLANK(G16),""," "&LOOKUP(G16,Articles!A:A,Articles!B:B)) &IF(ISBLANK(H16),""," "&LOOKUP(H16,'Objets de gestion'!C:C,'Objets de gestion'!E:E)) )) | M16: =IF(AND(ISBLANK(A16),ISBLANK(B16)),"",IF(OR(ISBLANK(A16),ISBLANK(B16)),"-", A16))
I17: =IF(AND(ISBLANK(A17),ISBLANK(B17)),"",IF(OR(ISBLANK(A17),ISBLANK(B17)),"-",LEN(Tableau47[[#This Row],[Colonne9]]))) | J17: =IF(AND(ISBLANK(A17),ISBLANK(B17)),"",IF(OR(ISBLANK(A17),ISBLANK(B17)),"à compléter", IF(H17=0,"",LOOKUP(H17,'Objets de gestion'!C:C,'Objets de gestion'!F:F)&"_") &IF(F17=0,"",LOOKUP(F17,'Objets de gestion'!C:C,'Objets de gestion'!F:F)&"_") &IF(D17=0,"",LOOKUP(D17,'Objets de gestion'!C:C,'Objets de gestion'!F:F)&"_") &IF(B17=0,"",LOOKUP(B17,'Objets de gestion'!C:C,'Objets de gestion'!F:F)) )) | K17: =IF(AND(ISBLANK(A17),ISBLANK(B17)),"",IF(OR(ISBLANK(A17),ISBLANK(B17)),"-", B17&" "&IF(ISBLANK(D17),"",C17&" "&D17&" ")&IF(ISBLANK(F17),"",E17&" "&F17&" ")&IF(ISBLANK(H17),"",G17&" "&H17&" "))) | L17: =IF(AND(ISBLANK(A17),ISBLANK(B17)),"",IF(OR(ISBLANK(A17),ISBLANK(B17)),"-", IF(ISBLANK(B17),"",LOOKUP(B17,'Objets de gestion'!C:C,'Objets de gestion'!E:E)) &IF(ISBLANK(C17),""," "&LOOKUP(C17,Articles!A:A,Articles!B:B)) &IF(ISBLANK(D17),""," "&LOOKUP(D17,'Objets de gestion'!C:C,'Objets de gestion'!E:E)) &IF(ISBLANK(E17),""," "&LOOKUP(E17,Articles!A:A,Articles!B:B)) &IF(ISBLANK(F17),""," "&LOOKUP(F17,'Objets de gestion'!C:C,'Objets de gestion'!E:E)) &IF(ISBLANK(G17),""," "&LOOKUP(G17,Articles!A:A,Articles!B:B)) &IF(ISBLANK(H17),""," "&LOOKUP(H17,'Objets de gestion'!C:C,'Objets de gestion'!E:E)) )) | M17: =IF(AND(ISBLANK(A17),ISBLANK(B17)),"",IF(OR(ISBLANK(A17),ISBLANK(B17)),"-", A17))
I18: =IF(AND(ISBLANK(A18),ISBLANK(B18)),"",IF(OR(ISBLANK(A18),ISBLANK(B18)),"-",LEN(Tableau47[[#This Row],[Colonne9]]))) | J18: =IF(AND(ISBLANK(A18),ISBLANK(B18)),"",IF(OR(ISBLANK(A18),ISBLANK(B18)),"à compléter", IF(H18=0,"",LOOKUP(H18,'Objets de gestion'!C:C,'Objets de gestion'!F:F)&"_") &IF(F18=0,"",LOOKUP(F18,'Objets de gestion'!C:C,'Objets de gestion'!F:F)&"_") &IF(D18=0,"",LOOKUP(D18,'Objets de gestion'!C:C,'Objets de gestion'!F:F)&"_") &IF(B18=0,"",LOOKUP(B18,'Objets de gestion'!C:C,'Objets de gestion'!F:F)) )) | K18: =IF(AND(ISBLANK(A18),ISBLANK(B18)),"",IF(OR(ISBLANK(A18),ISBLANK(B18)),"-", B18&" "&IF(ISBLANK(D18),"",C18&" "&D18&" ")&IF(ISBLANK(F18),"",E18&" "&F18&" ")&IF(ISBLANK(H18),"",G18&" "&H18&" "))) | L18: =IF(AND(ISBLANK(A18),ISBLANK(B18)),"",IF(OR(ISBLANK(A18),ISBLANK(B18)),"-", IF(ISBLANK(B18),"",LOOKUP(B18,'Objets de gestion'!C:C,'Objets de gestion'!E:E)) &IF(ISBLANK(C18),""," "&LOOKUP(C18,Articles!A:A,Articles!B:B)) &IF(ISBLANK(D18),""," "&LOOKUP(D18,'Objets de gestion'!C:C,'Objets de gestion'!E:E)) &IF(ISBLANK(E18),""," "&LOOKUP(E18,Articles!A:A,Articles!B:B)) &IF(ISBLANK(F18),""," "&LOOKUP(F18,'Objets de gestion'!C:C,'Objets de gestion'!E:E)) &IF(ISBLANK(G18),""," "&LOOKUP(G18,Articles!A:A,Articles!B:B)) &IF(ISBLANK(H18),""," "&LOOKUP(H18,'Objets de gestion'!C:C,'Objets de gestion'!E:E)) )) | M18: =IF(AND(ISBLANK(A18),ISBLANK(B18)),"",IF(OR(ISBLANK(A18),ISBLANK(B18)),"-", A18))
I19: =IF(AND(ISBLANK(A19),ISBLANK(B19)),"",IF(OR(ISBLANK(A19),ISBLANK(B19)),"-",LEN(Tableau47[[#This Row],[Colonne9]]))) | J19: =IF(AND(ISBLANK(A19),ISBLANK(B19)),"",IF(OR(ISBLANK(A19),ISBLANK(B19)),"à compléter", IF(H19=0,"",LOOKUP(H19,'Objets de gestion'!C:C,'Objets de gestion'!F:F)&"_") &IF(F19=0,"",LOOKUP(F19,'Objets de gestion'!C:C,'Objets de gestion'!F:F)&"_") &IF(D19=0,"",LOOKUP(D19,'Objets de gestion'!C:C,'Objets de gestion'!F:F)&"_") &IF(B19=0,"",LOOKUP(B19,'Objets de gestion'!C:C,'Objets de gestion'!F:F)) )) | K19: =IF(AND(ISBLANK(A19),ISBLANK(B19)),"",IF(OR(ISBLANK(A19),ISBLANK(B19)),"-", B19&" "&IF(ISBLANK(D19),"",C19&" "&D19&" ")&IF(ISBLANK(F19),"",E19&" "&F19&" ")&IF(ISBLANK(H19),"",G19&" "&H19&" "))) | L19: =IF(AND(ISBLANK(A19),ISBLANK(B19)),"",IF(OR(ISBLANK(A19),ISBLANK(B19)),"-", IF(ISBLANK(B19),"",LOOKUP(B19,'Objets de gestion'!C:C,'Objets de gestion'!E:E)) &IF(ISBLANK(C19),""," "&LOOKUP(C19,Articles!A:A,Articles!B:B)) &IF(ISBLANK(D19),""," "&LOOKUP(D19,'Objets de gestion'!C:C,'Objets de gestion'!E:E)) &IF(ISBLANK(E19),""," "&LOOKUP(E19,Articles!A:A,Articles!B:B)) &IF(ISBLANK(F19),""," "&LOOKUP(F19,'Objets de gestion'!C:C,'Objets de gestion'!E:E)) &IF(ISBLANK(G19),""," "&LOOKUP(G19,Articles!A:A,Articles!B:B)) &IF(ISBLANK(H19),""," "&LOOKUP(H19,'Objets de gestion'!C:C,'Objets de gestion'!E:E)) )) | M19: =IF(AND(ISBLANK(A19),ISBLANK(B19)),"",IF(OR(ISBLANK(A19),ISBLANK(B19)),"-", A19))
... I157: =IF(AND(ISBLANK(A157),ISBLANK(B157)),"",IF(OR(ISBLANK(A157),ISBLANK(B157)),"-",LEN(Tableau47[[#This Row],[Colonne9]]))) | J157: =IF(AND(ISBLANK(A157),ISBLANK(B157)),"",IF(OR(ISBLANK(A157),ISBLANK(B157)),"à compléter", IF(H157=0,"",LOOKUP(H157,'Objets de gestion'!C:C,'Objets de gestion'!F:F)&"_") &IF(F157=0,"",LOOKUP(F157,'Objets de gestion'!C:C,'Objets de gestion'!F:F)&"_") &IF(D157=0,"",LOOKUP(D157,'Objets de gestion'!C:C,'Objets de gestion'!F:F)&"_") &IF(B157=0,"",LOOKUP(B157,'Objets de gestion'!C:C,'Objets de gestion'!F:F)) )) | K157: =IF(AND(ISBLANK(A157),ISBLANK(B157)),"",IF(OR(ISBLANK(A157),ISBLANK(B157)),"-", B157&" "&IF(ISBLANK(D157),"",C157&" "&D157&" ")&IF(ISBLANK(F157),"",E157&" "&F157&" ")&IF(ISBLANK(H157),"",G157&" "&H157&" "))) | L157: =IF(AND(ISBLANK(A157),ISBLANK(B157)),"",IF(OR(ISBLANK(A157),ISBLANK(B157)),"-", IF(ISBLANK(B157),"",LOOKUP(B157,'Objets de gestion'!C:C,'Objets de gestion'!E:E)) &IF(ISBLANK(C157),""," "&LOOKUP(C157,Articles!A:A,Articles!B:B)) &IF(ISBLANK(D157),""," "&LOOKUP(D157,'Objets de gestion'!C:C,'Objets de gestion'!E:E)) &IF(ISBLANK(E157),""," "&LOOKUP(E157,Articles!A:A,Articles!B:B)) &IF(ISBLANK(F157),""," "&LOOKUP(F157,'Objets de gestion'!C:C,'Objets de gestion'!E:E)) &IF(ISBLANK(G157),""," "&LOOKUP(G157,Articles!A:A,Articles!B:B)) &IF(ISBLANK(H157),""," "&LOOKUP(H157,'Objets de gestion'!C:C,'Objets de gestion'!E:E)) )) | M157: =IF(AND(ISBLANK(A157),ISBLANK(B157)),"",IF(OR(ISBLANK(A157),ISBLANK(B157)),"-", A157))

Sheet Objets de gestion
A1: Date ajout | B1: Used | C1: Nom FR | D1: Définition unique | E1: Nom EN | F1: Trigramme
A2: 43868 | C2: "a l'autorité parentale" | E2: "got the parental authority" | F2: GOTPAAAHR
A3: 43868 | C3: "a le pouvoir bancaire" | E3: "got the banking power" | F3: GOTBNKPOW
A4: 43867 | C4: "a une entreprise individuelle" | E4: "got an individual company" | F4: GOTIDVCNY
A5: 43868 | C5: "appartient au foyer fiscal" | E5: "belonging to the fiscal household" | F5: BLGFSCHHD
A6: 43868 | C6: "bénéficiaire effectif" | E6: "effective beneficiary" | F6: EFTBEN
A7: 43392 | C7: "Centre Est Europe" | E7: "Centre Est Europe" | F7: CEE
A8: 44018 | C8: 36 derniers mois | E8: last 36 months | F8: LST36M
A9: 44199 | C9: à payer | E9: required to pay | F9: RTP
A10: 44199 | C10: abonné | E10: subscriber | F10: SBC
A11: 44199 | C11: absence | E11: absence | F11: ABS
A12: 43724 | C12: ACAM | D12: Autorité de Contrôle des Assurances et des Mutuelles | E12: ACAM | F12: AAM
A13: 44082 | C13: accès | E13: access | F13: AKS
A14: 44082 | C14: accès confidentiel | E14: confidential access | F14: CFDAKS
A15: 44040 | C15: accident | E15: accident | F15: ACD
A16: 44054 | C16: accident de circulation | E16: Traffic accident | F16: TFFACD
A17: 44012 | C17: accord de gestion | E17: management agreement | F17: MGTAGM
A18: 44049 | C18: accouchement | E18: delivery | F18: DLY
A19: 43719 | C19: ACEM | D19: Action Clé En Main | E19: turnkey action | F19: TNKACT
A20: 43721 | C20: ACEM réalisée | E20: turnkey action completion | F20: TNKACTCPI
A21: 43860 | C21: acheminement | E21: transit | F21: TAS
A22: 43448 | C22: ACM | E22: ACM | F22: ACM
A23: 43760 | C23: ACORES | E23: ACORES | F23: ACE
A24: 44199 | C24: acquisition | E24: acquisition | F24: ACQ
A25: 43740 | C25: acte CCAM | E25: health care act CCAM | F25: HCACAM
A26: 43741 | C26: acte de prévention | E26: prevention health care act | F26: PVEHCA
A27: 43465 | C27: acte de soins santé de la CPAM | E27: heath care act CPAM | F27: HCACPM
A28: 43465 | C28: acte de soins santé des ACM | E28: health care act ACM | F28: HCAACM
A29: 44301 | B29: 1 | C29: Acte fondateur | E29: Founder act | F29: FUDACT
A30: 43448 | C30: acteur | D30: référentiel Acteur SIO | E30: actor | F30: AOR
A31: 43887 | C31: acteur en assurance | E31: insurance actor | F31: INSAOR
A32: 43469 | C32: acteur santé | E32: health actor | F32: HELAOR
A33: 44199 | C33: actif | E33: active | F33: ACV
A34: 44172 | C34: actif supprimable | E34: removable asset | F34: RMVAST
A35: 43608 | C35: action | E35: action | F35: ACT
A36: 44083 | C36: action du contentieux | E36: litigation action | F36: LITACT
A37: 43815 | C37: action suivante | E37: next action | F37: NXTACT
A38: 43868 | C38: actionnaire | E38: shareholder | F38: SHH
A39: 43384 | C39: activité | E39: activity | F39: AVY
A40: 44055 | C40: activité à mi-temps | E40: half-time activity | F40: HTMAVY
...

Sheet Articles
A1: Nom fr | B1: Nom en
A3: , | B3: ,
A4: à | B4: to
A5: à la | B5: to
A6: à un | B6: to
A7: à qui | B7: to
A8: après | B8: after
A9: au | B9: to
A10: avec | B10: with
A11: chez | B11: at
A12: d' | B12: of the
A13: dans | B13: in
... A43: sur le | B43: on the

Sheet BIB
A1: Nom du BIB | B1: ID Table | C1: ROBIN | D1: Nom anglais | E1: Code du BIB | F1: Remarque
A2: Abstraction / transcodification | B2: TID | C2: IBIT | D2: Abstraction / transcoding | E2: ABN
A3: Acteur en assurance | B3: AAC | C3: IBIA | D3: Insurance Actor | E3: INSAOR
A4: Avantages | B4: FAV | C4: IBIF | D4: Advantages | E4: INSCTRADV
A5: Balances analytiques comptables | B5: FBA | C5: IBIF | D5: Analytical accounting balances | E5: CSTACGBAL
A6: Barème santé | B6: RBS | C6: IBIR | D6: Health Scale | E6: HELSCA
A7: Bascule CAM vers GEC | B7: CCG | C7: IBIC | D7: Transfer CAM to GEC | E7: TRFCAMGEC
A8: Base collecte | B8: TCO | C8: SIAD | D8: Collecte database | E8: COLDBA
A9: Base organisme | B9: RBO | C9: IBIR | D9: Organisation Repository | E9: BSEORG
A10: Bénéficiaires en assurance | B10: AIB | C10: IBIA | D10: insurance beneficiary | E10: INSBEN
A11: BIB pour stocker les tables EOLE : TAWISTF, TAWISTG... | B11: VSI | C11: IBIV | E11: SIOEOLE
A12: Carte avance santé | B12: SCS | C12: IBIS | D12: Advance Health Card | E12: AHC
A13: COFIDIS Données externes | B13: OCF | C13: IBIO | D13: Cofidis external data | E13: CFSXTRDTA
A14: Collaborateurs Assurance | B14: RCB | C14: IBIR | D14: Insurance collaborators | E14: INSCBR
A15: Comptabilité | B15: FCO | C15: IBIF | D15: Accounting | E15: INSCNYACGREC
A16: Comptage Volumétrie | B16: TVC | C16: IBIT | D16: Volumetry Count
A17: Conditions et moyens de paiement | B17: CMP | C17: IBIC | D17: Payment means and conditions | E17: PMC
A18: Console du gestionnaire | B18: MCG | C18: IBIM | D18: Manager console | E18: INSMGRCON
A19: Contentieux | B19: CTX | C19: IBIC | D19: Litigation | E19: LIT
A20: Contrat | B20: CCT | C20: IBIC | D20: contract | E20: INSCTR
A21: Contrat assurance téléphone | B21: CTE | C21: IBIC | D21: Insurance contract telephone | E21: INSTEL
A22: Contrat prévoyance | B22: CVE | C22: IBIC | D22: prevention contract | E22: PVECTR
A23: Correspondant | B23: ACO | C23: IBIA | D23: corresponding | E23: INSCOR
A24: Courtier | B24: ECO | C24: IBIE | D24: broker | E24: INSBRK
A25: Datamart Contrat | B25: DCT | C25: IBID | D25: contract datamart | E25: CTR
A26: Datamart courtiers | B26: BDT | C26: IBID | D26: broker datamart | E26: BRK
A27: Déclaratif réglementaire Belgique | B27: OBR | C27: IBIO | D27: Belgian regulatory report | E27: BELRGLRPT
A28: Dettes | B28: SDE | C28: IBIS | D28: Debts | E28: INSDET
... A31: Echéancier des contrats d’assurance | B31: FEC | C31: IBIF | D31: Schedule of insurance contracts | E31: SCHINSCTR
A32: EOLE | B32: CEO | C32: IBIC | D32: Eole
A33: Etude assurance | B33: VEA | C33: IBIV | D33: Insurance study | E33: INSSTU | F33: INSSTY
A34: Financier | B34: FFI | C34: IBIF | D34: Financial | E34: INSBUSFIN
A35: Financier et échéancier des sinistres | B35: SFS | C35: IBIS | D35: Financial schedule of claim | E35: FINSCHCIM
A36: Fiscalité des contrats d'assurance | B36: FFS | C36: IBIF | D36: Insurance contract fiscality | E36: INSCTRFSC
A37: Générateur des modèles de données des vues du SIAD | B37: TMV | C37: IBIT | D37: View model generator | E37: VIEMDEGTR
A38: GENESYS | B38: MGE | C38: IBIM | D38: genesys | E38: INSCTCPLF
A39: Gestion des documents assurance (IDOFCD) | B39: MDO | C39: IBIM | D39: Insurance document management | E39: INSDOCMGT
A40: Gestion des FOCUS | B40: MFO | C40: IBIM | D40: Insurance monitoring Focus | E40: INSMNTFOC
A41: Gestion du personnel assurance | B41: MPA | C41: IBIM | D41: Insurance Staff Management | E41: INSSFFMGT
A42: Images Contrats Assurance | B42: CIC | C42: IBIC | D42: Insurance Contract Image | E42: ICA | F42: à créer dans MAD
...

Sheet Type de table
A1: Catégorie | B1: ID | C1: Nom | D1: Définition unique | E1: libellé FR | F1: Libellé EN
A2: Technique | B2: A | C2: Abstraction | D2: entité qui continet les clés techniques SID générées à partir des clés SIO | E2: Table d'abstraction | F2: Abstraction table
A3: Métier | B3: X | C3: Axe d'analyse | D3: Dimension qui servira d'axe d'analyse | E3: Axe | F3: Axis
A4: Métier | B4: M | C4: Datamart | D4: table qui agrège une table de fait et ses dimensions attenantes pour répondre à un besoin fonctionnel | E4: Datamart | F4: Datamart
